2025-03-18 01:21:52,083 INFO    MainThread:1694815 [wandb_setup.py:_flush():67] Current SDK version is 0.19.8
2025-03-18 01:21:52,084 INFO    MainThread:1694815 [wandb_setup.py:_flush():67] Configure stats pid to 1694815
2025-03-18 01:21:52,084 INFO    MainThread:1694815 [wandb_setup.py:_flush():67] Loading settings from /home/jaansi/.config/wandb/settings
2025-03-18 01:21:52,084 INFO    MainThread:1694815 [wandb_setup.py:_flush():67] Loading settings from /home/jaansi/fa24-nmep-hw2/wandb/settings
2025-03-18 01:21:52,084 INFO    MainThread:1694815 [wandb_setup.py:_flush():67] Loading settings from environment variables
2025-03-18 01:21:52,084 INFO    MainThread:1694815 [wandb_init.py:setup_run_log_directory():647] Logging user logs to /home/jaansi/fa24-nmep-hw2/wandb/run-20250318_012152-o1i9usk1/logs/debug.log
2025-03-18 01:21:52,084 INFO    MainThread:1694815 [wandb_init.py:setup_run_log_directory():648] Logging internal logs to /home/jaansi/fa24-nmep-hw2/wandb/run-20250318_012152-o1i9usk1/logs/debug-internal.log
2025-03-18 01:21:52,084 INFO    MainThread:1694815 [wandb_init.py:init():761] calling init triggers
2025-03-18 01:21:52,084 INFO    MainThread:1694815 [wandb_init.py:init():766] wandb.init called with sweep_config: {}
config: {'BASE': [''], 'DATA': CfgNode({'BATCH_SIZE': 2048, 'DATA_PATH': '', 'DATASET': 'cifar10', 'IMG_SIZE': 70, 'INTERPOLATION': 'bicubic', 'PIN_MEMORY': True, 'NUM_WORKERS': 32}), 'MODEL': CfgNode({'NAME': 'alexnet', 'RESUME': '', 'NUM_CLASSES': 200, 'DROP_RATE': 0.0, 'RESNET': CfgNode({})}), 'TRAIN': CfgNode({'START_EPOCH': 0, 'EPOCHS': 50, 'WARMUP_EPOCHS': 10, 'LR': 0.0003, 'MIN_LR': 3e-05, 'WARMUP_LR': 3e-05, 'ACCUMULATION_STEPS': 1, 'LR_SCHEDULER': CfgNode({'NAME': 'cosine'}), 'OPTIMIZER': CfgNode({'NAME': 'adamw', 'EPS': 1e-08, 'BETAS': (0.9, 0.999), 'MOMENTUM': 0.9})}), 'AUG': CfgNode({'COLOR_JITTER': 0.4, 'RAND_AUGMENT': 'rand-m9-mstd0.5-inc1'}), 'TEST': CfgNode({'CROP': True, 'SEQUENTIAL': False, 'SHUFFLE': False}), 'OUTPUT': 'output/alexnet', 'SAVE_FREQ': 5, 'PRINT_FREQ': 99999, 'SEED': 0, 'EVAL_MODE': False, '_wandb': {}}
2025-03-18 01:21:52,084 INFO    MainThread:1694815 [wandb_init.py:init():784] starting backend
2025-03-18 01:21:52,084 INFO    MainThread:1694815 [wandb_init.py:init():788] sending inform_init request
2025-03-18 01:21:52,087 INFO    MainThread:1694815 [backend.py:_multiprocessing_setup():101] multiprocessing start_methods=fork,spawn,forkserver, using: spawn
2025-03-18 01:21:52,087 INFO    MainThread:1694815 [wandb_init.py:init():798] backend started and connected
2025-03-18 01:21:52,089 INFO    MainThread:1694815 [wandb_init.py:init():891] updated telemetry
2025-03-18 01:21:52,094 INFO    MainThread:1694815 [wandb_init.py:init():915] communicating run to backend with 90.0 second timeout
2025-03-18 01:21:52,442 INFO    MainThread:1694815 [wandb_init.py:init():990] starting run threads in backend
2025-03-18 01:21:52,519 INFO    MainThread:1694815 [wandb_run.py:_console_start():2375] atexit reg
2025-03-18 01:21:52,520 INFO    MainThread:1694815 [wandb_run.py:_redirect():2227] redirect: wrap_raw
2025-03-18 01:21:52,520 INFO    MainThread:1694815 [wandb_run.py:_redirect():2292] Wrapping output streams.
2025-03-18 01:21:52,520 INFO    MainThread:1694815 [wandb_run.py:_redirect():2315] Redirects installed.
2025-03-18 01:21:52,522 INFO    MainThread:1694815 [wandb_init.py:init():1032] run started, returning control to user process
2025-03-18 01:24:08,762 INFO    MsgRouterThr:1694815 [mailbox.py:close():129] Closing mailbox, abandoning 1 handles.
2025-03-18 01:24:09,462 ERROR   Thread-18 (_pin_memory_loop):1694815 [redirect.py:_on_write():661] error in stderr callback
Traceback (most recent call last):
  File "/home/jaansi/miniconda3/lib/python3.12/threading.py", line 1075, in _bootstrap_inner
    self.run()
  File "/home/jaansi/miniconda3/lib/python3.12/threading.py", line 1012, in run
    self._target(*self._args, **self._kwargs)
  File "/home/jaansi/miniconda3/lib/python3.12/site-packages/torch/utils/data/_utils/pin_memory.py", line 59, in _pin_memory_loop
    do_one_step()
  File "/home/jaansi/miniconda3/lib/python3.12/site-packages/torch/utils/data/_utils/pin_memory.py", line 35, in do_one_step
    r = in_queue.get(timeout=MP_STATUS_CHECK_INTERVAL)
        ^^^^^^^^^^^^^^^^^^^^^^^^^^^^^^^^^^^^^^^^^^^^^^
  File "/home/jaansi/miniconda3/lib/python3.12/multiprocessing/queues.py", line 122, in get
    return _ForkingPickler.loads(res)
           ^^^^^^^^^^^^^^^^^^^^^^^^^^
  File "/home/jaansi/miniconda3/lib/python3.12/site-packages/torch/multiprocessing/reductions.py", line 541, in rebuild_storage_fd
    fd = df.detach()
         ^^^^^^^^^^^
  File "/home/jaansi/miniconda3/lib/python3.12/multiprocessing/resource_sharer.py", line 57, in detach
    with _resource_sharer.get_connection(self._id) as conn:
         ^^^^^^^^^^^^^^^^^^^^^^^^^^^^^^^^^^^^^^^^^
  File "/home/jaansi/miniconda3/lib/python3.12/multiprocessing/resource_sharer.py", line 86, in get_connection
    c = Client(address, authkey=process.current_process().authkey)
        ^^^^^^^^^^^^^^^^^^^^^^^^^^^^^^^^^^^^^^^^^^^^^^^^^^^^^^^^^^
  File "/home/jaansi/miniconda3/lib/python3.12/multiprocessing/connection.py", line 525, in Client
    answer_challenge(c, authkey)
  File "/home/jaansi/miniconda3/lib/python3.12/multiprocessing/connection.py", line 953, in answer_challenge
    message = connection.recv_bytes(256)         # reject large message
              ^^^^^^^^^^^^^^^^^^^^^^^^^^
  File "/home/jaansi/miniconda3/lib/python3.12/multiprocessing/connection.py", line 216, in recv_bytes
    buf = self._recv_bytes(maxlength)
          ^^^^^^^^^^^^^^^^^^^^^^^^^^^
  File "/home/jaansi/miniconda3/lib/python3.12/multiprocessing/connection.py", line 430, in _recv_bytes
    buf = self._recv(4)
          ^^^^^^^^^^^^^
  File "/home/jaansi/miniconda3/lib/python3.12/multiprocessing/connection.py", line 395, in _recv
    chunk = read(handle, remaining)
            ^^^^^^^^^^^^^^^^^^^^^^^
ConnectionResetError: [Errno 104] Connection reset by peer

During handling of the above exception, another exception occurred:

Traceback (most recent call last):
  File "/home/jaansi/miniconda3/lib/python3.12/site-packages/wandb/sdk/lib/redirect.py", line 659, in _on_write
    cb(written_data)
  File "/home/jaansi/miniconda3/lib/python3.12/site-packages/wandb/sdk/wandb_run.py", line 2302, in <lambda>
    lambda data: self._console_raw_callback("stderr", data),
                 ^^^^^^^^^^^^^^^^^^^^^^^^^^^^^^^^^^^^^^^^^^
  File "/home/jaansi/miniconda3/lib/python3.12/site-packages/wandb/sdk/wandb_run.py", line 401, in wrapper_fn
    return func(self, *args, **kwargs)
           ^^^^^^^^^^^^^^^^^^^^^^^^^^^
  File "/home/jaansi/miniconda3/lib/python3.12/site-packages/wandb/sdk/wandb_run.py", line 1444, in _console_raw_callback
    self._backend.interface.publish_output_raw(name, data)
  File "/home/jaansi/miniconda3/lib/python3.12/site-packages/wandb/sdk/interface/interface.py", line 761, in publish_output_raw
    self._publish_output_raw(o)
  File "/home/jaansi/miniconda3/lib/python3.12/site-packages/wandb/sdk/interface/interface_shared.py", line 38, in _publish_output_raw
    self._publish(rec)
  File "/home/jaansi/miniconda3/lib/python3.12/site-packages/wandb/sdk/interface/interface_sock.py", line 39, in _publish
    self._sock_client.send_record_publish(record)
  File "/home/jaansi/miniconda3/lib/python3.12/site-packages/wandb/sdk/lib/sock_client.py", line 174, in send_record_publish
    self.send_server_request(server_req)
  File "/home/jaansi/miniconda3/lib/python3.12/site-packages/wandb/sdk/lib/sock_client.py", line 154, in send_server_request
    self._send_message(msg)
  File "/home/jaansi/miniconda3/lib/python3.12/site-packages/wandb/sdk/lib/sock_client.py", line 151, in _send_message
    self._sendall_with_error_handle(header + data)
  File "/home/jaansi/miniconda3/lib/python3.12/site-packages/wandb/sdk/lib/sock_client.py", line 130, in _sendall_with_error_handle
    sent = self._sock.send(data)
           ^^^^^^^^^^^^^^^^^^^^^
BrokenPipeError: [Errno 32] Broken pipe
2025-03-18 01:24:09,469 ERROR   Thread-18 (_pin_memory_loop):1694815 [redirect.py:_on_write():661] error in stderr callback
Traceback (most recent call last):
  File "/home/jaansi/miniconda3/lib/python3.12/threading.py", line 1075, in _bootstrap_inner
    self.run()
  File "/home/jaansi/miniconda3/lib/python3.12/threading.py", line 1012, in run
    self._target(*self._args, **self._kwargs)
  File "/home/jaansi/miniconda3/lib/python3.12/site-packages/torch/utils/data/_utils/pin_memory.py", line 59, in _pin_memory_loop
    do_one_step()
  File "/home/jaansi/miniconda3/lib/python3.12/site-packages/torch/utils/data/_utils/pin_memory.py", line 35, in do_one_step
    r = in_queue.get(timeout=MP_STATUS_CHECK_INTERVAL)
        ^^^^^^^^^^^^^^^^^^^^^^^^^^^^^^^^^^^^^^^^^^^^^^
  File "/home/jaansi/miniconda3/lib/python3.12/multiprocessing/queues.py", line 122, in get
    return _ForkingPickler.loads(res)
           ^^^^^^^^^^^^^^^^^^^^^^^^^^
  File "/home/jaansi/miniconda3/lib/python3.12/site-packages/torch/multiprocessing/reductions.py", line 541, in rebuild_storage_fd
    fd = df.detach()
         ^^^^^^^^^^^
  File "/home/jaansi/miniconda3/lib/python3.12/multiprocessing/resource_sharer.py", line 57, in detach
    with _resource_sharer.get_connection(self._id) as conn:
         ^^^^^^^^^^^^^^^^^^^^^^^^^^^^^^^^^^^^^^^^^
  File "/home/jaansi/miniconda3/lib/python3.12/multiprocessing/resource_sharer.py", line 86, in get_connection
    c = Client(address, authkey=process.current_process().authkey)
        ^^^^^^^^^^^^^^^^^^^^^^^^^^^^^^^^^^^^^^^^^^^^^^^^^^^^^^^^^^
  File "/home/jaansi/miniconda3/lib/python3.12/multiprocessing/connection.py", line 525, in Client
    answer_challenge(c, authkey)
  File "/home/jaansi/miniconda3/lib/python3.12/multiprocessing/connection.py", line 953, in answer_challenge
    message = connection.recv_bytes(256)         # reject large message
              ^^^^^^^^^^^^^^^^^^^^^^^^^^
  File "/home/jaansi/miniconda3/lib/python3.12/multiprocessing/connection.py", line 216, in recv_bytes
    buf = self._recv_bytes(maxlength)
          ^^^^^^^^^^^^^^^^^^^^^^^^^^^
  File "/home/jaansi/miniconda3/lib/python3.12/multiprocessing/connection.py", line 430, in _recv_bytes
    buf = self._recv(4)
          ^^^^^^^^^^^^^
  File "/home/jaansi/miniconda3/lib/python3.12/multiprocessing/connection.py", line 395, in _recv
    chunk = read(handle, remaining)
            ^^^^^^^^^^^^^^^^^^^^^^^
ConnectionResetError: [Errno 104] Connection reset by peer

During handling of the above exception, another exception occurred:

Traceback (most recent call last):
  File "/home/jaansi/miniconda3/lib/python3.12/site-packages/wandb/sdk/lib/redirect.py", line 659, in _on_write
    cb(written_data)
  File "/home/jaansi/miniconda3/lib/python3.12/site-packages/wandb/sdk/wandb_run.py", line 2302, in <lambda>
    lambda data: self._console_raw_callback("stderr", data),
                 ^^^^^^^^^^^^^^^^^^^^^^^^^^^^^^^^^^^^^^^^^^
  File "/home/jaansi/miniconda3/lib/python3.12/site-packages/wandb/sdk/wandb_run.py", line 401, in wrapper_fn
    return func(self, *args, **kwargs)
           ^^^^^^^^^^^^^^^^^^^^^^^^^^^
  File "/home/jaansi/miniconda3/lib/python3.12/site-packages/wandb/sdk/wandb_run.py", line 1444, in _console_raw_callback
    self._backend.interface.publish_output_raw(name, data)
  File "/home/jaansi/miniconda3/lib/python3.12/site-packages/wandb/sdk/interface/interface.py", line 761, in publish_output_raw
    self._publish_output_raw(o)
  File "/home/jaansi/miniconda3/lib/python3.12/site-packages/wandb/sdk/interface/interface_shared.py", line 38, in _publish_output_raw
    self._publish(rec)
  File "/home/jaansi/miniconda3/lib/python3.12/site-packages/wandb/sdk/interface/interface_sock.py", line 39, in _publish
    self._sock_client.send_record_publish(record)
  File "/home/jaansi/miniconda3/lib/python3.12/site-packages/wandb/sdk/lib/sock_client.py", line 174, in send_record_publish
    self.send_server_request(server_req)
  File "/home/jaansi/miniconda3/lib/python3.12/site-packages/wandb/sdk/lib/sock_client.py", line 154, in send_server_request
    self._send_message(msg)
  File "/home/jaansi/miniconda3/lib/python3.12/site-packages/wandb/sdk/lib/sock_client.py", line 151, in _send_message
    self._sendall_with_error_handle(header + data)
  File "/home/jaansi/miniconda3/lib/python3.12/site-packages/wandb/sdk/lib/sock_client.py", line 130, in _sendall_with_error_handle
    sent = self._sock.send(data)
           ^^^^^^^^^^^^^^^^^^^^^
BrokenPipeError: [Errno 32] Broken pipe
2025-03-18 01:24:09,471 ERROR   Thread-18 (_pin_memory_loop):1694815 [redirect.py:_on_write():661] error in stderr callback
Traceback (most recent call last):
  File "/home/jaansi/miniconda3/lib/python3.12/threading.py", line 1075, in _bootstrap_inner
    self.run()
  File "/home/jaansi/miniconda3/lib/python3.12/threading.py", line 1012, in run
    self._target(*self._args, **self._kwargs)
  File "/home/jaansi/miniconda3/lib/python3.12/site-packages/torch/utils/data/_utils/pin_memory.py", line 59, in _pin_memory_loop
    do_one_step()
  File "/home/jaansi/miniconda3/lib/python3.12/site-packages/torch/utils/data/_utils/pin_memory.py", line 35, in do_one_step
    r = in_queue.get(timeout=MP_STATUS_CHECK_INTERVAL)
        ^^^^^^^^^^^^^^^^^^^^^^^^^^^^^^^^^^^^^^^^^^^^^^
  File "/home/jaansi/miniconda3/lib/python3.12/multiprocessing/queues.py", line 122, in get
    return _ForkingPickler.loads(res)
           ^^^^^^^^^^^^^^^^^^^^^^^^^^
  File "/home/jaansi/miniconda3/lib/python3.12/site-packages/torch/multiprocessing/reductions.py", line 541, in rebuild_storage_fd
    fd = df.detach()
         ^^^^^^^^^^^
  File "/home/jaansi/miniconda3/lib/python3.12/multiprocessing/resource_sharer.py", line 57, in detach
    with _resource_sharer.get_connection(self._id) as conn:
         ^^^^^^^^^^^^^^^^^^^^^^^^^^^^^^^^^^^^^^^^^
  File "/home/jaansi/miniconda3/lib/python3.12/multiprocessing/resource_sharer.py", line 86, in get_connection
    c = Client(address, authkey=process.current_process().authkey)
        ^^^^^^^^^^^^^^^^^^^^^^^^^^^^^^^^^^^^^^^^^^^^^^^^^^^^^^^^^^
  File "/home/jaansi/miniconda3/lib/python3.12/multiprocessing/connection.py", line 525, in Client
    answer_challenge(c, authkey)
  File "/home/jaansi/miniconda3/lib/python3.12/multiprocessing/connection.py", line 953, in answer_challenge
    message = connection.recv_bytes(256)         # reject large message
              ^^^^^^^^^^^^^^^^^^^^^^^^^^
  File "/home/jaansi/miniconda3/lib/python3.12/multiprocessing/connection.py", line 216, in recv_bytes
    buf = self._recv_bytes(maxlength)
          ^^^^^^^^^^^^^^^^^^^^^^^^^^^
  File "/home/jaansi/miniconda3/lib/python3.12/multiprocessing/connection.py", line 430, in _recv_bytes
    buf = self._recv(4)
          ^^^^^^^^^^^^^
  File "/home/jaansi/miniconda3/lib/python3.12/multiprocessing/connection.py", line 395, in _recv
    chunk = read(handle, remaining)
            ^^^^^^^^^^^^^^^^^^^^^^^
ConnectionResetError: [Errno 104] Connection reset by peer

During handling of the above exception, another exception occurred:

Traceback (most recent call last):
  File "/home/jaansi/miniconda3/lib/python3.12/site-packages/wandb/sdk/lib/redirect.py", line 659, in _on_write
    cb(written_data)
  File "/home/jaansi/miniconda3/lib/python3.12/site-packages/wandb/sdk/wandb_run.py", line 2302, in <lambda>
    lambda data: self._console_raw_callback("stderr", data),
                 ^^^^^^^^^^^^^^^^^^^^^^^^^^^^^^^^^^^^^^^^^^
  File "/home/jaansi/miniconda3/lib/python3.12/site-packages/wandb/sdk/wandb_run.py", line 401, in wrapper_fn
    return func(self, *args, **kwargs)
           ^^^^^^^^^^^^^^^^^^^^^^^^^^^
  File "/home/jaansi/miniconda3/lib/python3.12/site-packages/wandb/sdk/wandb_run.py", line 1444, in _console_raw_callback
    self._backend.interface.publish_output_raw(name, data)
  File "/home/jaansi/miniconda3/lib/python3.12/site-packages/wandb/sdk/interface/interface.py", line 761, in publish_output_raw
    self._publish_output_raw(o)
  File "/home/jaansi/miniconda3/lib/python3.12/site-packages/wandb/sdk/interface/interface_shared.py", line 38, in _publish_output_raw
    self._publish(rec)
  File "/home/jaansi/miniconda3/lib/python3.12/site-packages/wandb/sdk/interface/interface_sock.py", line 39, in _publish
    self._sock_client.send_record_publish(record)
  File "/home/jaansi/miniconda3/lib/python3.12/site-packages/wandb/sdk/lib/sock_client.py", line 174, in send_record_publish
    self.send_server_request(server_req)
  File "/home/jaansi/miniconda3/lib/python3.12/site-packages/wandb/sdk/lib/sock_client.py", line 154, in send_server_request
    self._send_message(msg)
  File "/home/jaansi/miniconda3/lib/python3.12/site-packages/wandb/sdk/lib/sock_client.py", line 151, in _send_message
    self._sendall_with_error_handle(header + data)
  File "/home/jaansi/miniconda3/lib/python3.12/site-packages/wandb/sdk/lib/sock_client.py", line 130, in _sendall_with_error_handle
    sent = self._sock.send(data)
           ^^^^^^^^^^^^^^^^^^^^^
BrokenPipeError: [Errno 32] Broken pipe
2025-03-18 01:24:09,473 ERROR   Thread-18 (_pin_memory_loop):1694815 [redirect.py:_on_write():661] error in stderr callback
Traceback (most recent call last):
  File "/home/jaansi/miniconda3/lib/python3.12/threading.py", line 1075, in _bootstrap_inner
    self.run()
  File "/home/jaansi/miniconda3/lib/python3.12/threading.py", line 1012, in run
    self._target(*self._args, **self._kwargs)
  File "/home/jaansi/miniconda3/lib/python3.12/site-packages/torch/utils/data/_utils/pin_memory.py", line 59, in _pin_memory_loop
    do_one_step()
  File "/home/jaansi/miniconda3/lib/python3.12/site-packages/torch/utils/data/_utils/pin_memory.py", line 35, in do_one_step
    r = in_queue.get(timeout=MP_STATUS_CHECK_INTERVAL)
        ^^^^^^^^^^^^^^^^^^^^^^^^^^^^^^^^^^^^^^^^^^^^^^
  File "/home/jaansi/miniconda3/lib/python3.12/multiprocessing/queues.py", line 122, in get
    return _ForkingPickler.loads(res)
           ^^^^^^^^^^^^^^^^^^^^^^^^^^
  File "/home/jaansi/miniconda3/lib/python3.12/site-packages/torch/multiprocessing/reductions.py", line 541, in rebuild_storage_fd
    fd = df.detach()
         ^^^^^^^^^^^
  File "/home/jaansi/miniconda3/lib/python3.12/multiprocessing/resource_sharer.py", line 57, in detach
    with _resource_sharer.get_connection(self._id) as conn:
         ^^^^^^^^^^^^^^^^^^^^^^^^^^^^^^^^^^^^^^^^^
  File "/home/jaansi/miniconda3/lib/python3.12/multiprocessing/resource_sharer.py", line 86, in get_connection
    c = Client(address, authkey=process.current_process().authkey)
        ^^^^^^^^^^^^^^^^^^^^^^^^^^^^^^^^^^^^^^^^^^^^^^^^^^^^^^^^^^
  File "/home/jaansi/miniconda3/lib/python3.12/multiprocessing/connection.py", line 525, in Client
    answer_challenge(c, authkey)
  File "/home/jaansi/miniconda3/lib/python3.12/multiprocessing/connection.py", line 953, in answer_challenge
    message = connection.recv_bytes(256)         # reject large message
              ^^^^^^^^^^^^^^^^^^^^^^^^^^
  File "/home/jaansi/miniconda3/lib/python3.12/multiprocessing/connection.py", line 216, in recv_bytes
    buf = self._recv_bytes(maxlength)
          ^^^^^^^^^^^^^^^^^^^^^^^^^^^
  File "/home/jaansi/miniconda3/lib/python3.12/multiprocessing/connection.py", line 430, in _recv_bytes
    buf = self._recv(4)
          ^^^^^^^^^^^^^
  File "/home/jaansi/miniconda3/lib/python3.12/multiprocessing/connection.py", line 395, in _recv
    chunk = read(handle, remaining)
            ^^^^^^^^^^^^^^^^^^^^^^^
ConnectionResetError: [Errno 104] Connection reset by peer

During handling of the above exception, another exception occurred:

Traceback (most recent call last):
  File "/home/jaansi/miniconda3/lib/python3.12/site-packages/wandb/sdk/lib/redirect.py", line 659, in _on_write
    cb(written_data)
  File "/home/jaansi/miniconda3/lib/python3.12/site-packages/wandb/sdk/wandb_run.py", line 2302, in <lambda>
    lambda data: self._console_raw_callback("stderr", data),
                 ^^^^^^^^^^^^^^^^^^^^^^^^^^^^^^^^^^^^^^^^^^
  File "/home/jaansi/miniconda3/lib/python3.12/site-packages/wandb/sdk/wandb_run.py", line 401, in wrapper_fn
    return func(self, *args, **kwargs)
           ^^^^^^^^^^^^^^^^^^^^^^^^^^^
  File "/home/jaansi/miniconda3/lib/python3.12/site-packages/wandb/sdk/wandb_run.py", line 1444, in _console_raw_callback
    self._backend.interface.publish_output_raw(name, data)
  File "/home/jaansi/miniconda3/lib/python3.12/site-packages/wandb/sdk/interface/interface.py", line 761, in publish_output_raw
    self._publish_output_raw(o)
  File "/home/jaansi/miniconda3/lib/python3.12/site-packages/wandb/sdk/interface/interface_shared.py", line 38, in _publish_output_raw
    self._publish(rec)
  File "/home/jaansi/miniconda3/lib/python3.12/site-packages/wandb/sdk/interface/interface_sock.py", line 39, in _publish
    self._sock_client.send_record_publish(record)
  File "/home/jaansi/miniconda3/lib/python3.12/site-packages/wandb/sdk/lib/sock_client.py", line 174, in send_record_publish
    self.send_server_request(server_req)
  File "/home/jaansi/miniconda3/lib/python3.12/site-packages/wandb/sdk/lib/sock_client.py", line 154, in send_server_request
    self._send_message(msg)
  File "/home/jaansi/miniconda3/lib/python3.12/site-packages/wandb/sdk/lib/sock_client.py", line 151, in _send_message
    self._sendall_with_error_handle(header + data)
  File "/home/jaansi/miniconda3/lib/python3.12/site-packages/wandb/sdk/lib/sock_client.py", line 130, in _sendall_with_error_handle
    sent = self._sock.send(data)
           ^^^^^^^^^^^^^^^^^^^^^
BrokenPipeError: [Errno 32] Broken pipe
2025-03-18 01:24:09,474 ERROR   Thread-18 (_pin_memory_loop):1694815 [redirect.py:_on_write():661] error in stderr callback
Traceback (most recent call last):
  File "/home/jaansi/miniconda3/lib/python3.12/threading.py", line 1075, in _bootstrap_inner
    self.run()
  File "/home/jaansi/miniconda3/lib/python3.12/threading.py", line 1012, in run
    self._target(*self._args, **self._kwargs)
  File "/home/jaansi/miniconda3/lib/python3.12/site-packages/torch/utils/data/_utils/pin_memory.py", line 59, in _pin_memory_loop
    do_one_step()
  File "/home/jaansi/miniconda3/lib/python3.12/site-packages/torch/utils/data/_utils/pin_memory.py", line 35, in do_one_step
    r = in_queue.get(timeout=MP_STATUS_CHECK_INTERVAL)
        ^^^^^^^^^^^^^^^^^^^^^^^^^^^^^^^^^^^^^^^^^^^^^^
  File "/home/jaansi/miniconda3/lib/python3.12/multiprocessing/queues.py", line 122, in get
    return _ForkingPickler.loads(res)
           ^^^^^^^^^^^^^^^^^^^^^^^^^^
  File "/home/jaansi/miniconda3/lib/python3.12/site-packages/torch/multiprocessing/reductions.py", line 541, in rebuild_storage_fd
    fd = df.detach()
         ^^^^^^^^^^^
  File "/home/jaansi/miniconda3/lib/python3.12/multiprocessing/resource_sharer.py", line 57, in detach
    with _resource_sharer.get_connection(self._id) as conn:
         ^^^^^^^^^^^^^^^^^^^^^^^^^^^^^^^^^^^^^^^^^
  File "/home/jaansi/miniconda3/lib/python3.12/multiprocessing/resource_sharer.py", line 86, in get_connection
    c = Client(address, authkey=process.current_process().authkey)
        ^^^^^^^^^^^^^^^^^^^^^^^^^^^^^^^^^^^^^^^^^^^^^^^^^^^^^^^^^^
  File "/home/jaansi/miniconda3/lib/python3.12/multiprocessing/connection.py", line 525, in Client
    answer_challenge(c, authkey)
  File "/home/jaansi/miniconda3/lib/python3.12/multiprocessing/connection.py", line 953, in answer_challenge
    message = connection.recv_bytes(256)         # reject large message
              ^^^^^^^^^^^^^^^^^^^^^^^^^^
  File "/home/jaansi/miniconda3/lib/python3.12/multiprocessing/connection.py", line 216, in recv_bytes
    buf = self._recv_bytes(maxlength)
          ^^^^^^^^^^^^^^^^^^^^^^^^^^^
  File "/home/jaansi/miniconda3/lib/python3.12/multiprocessing/connection.py", line 430, in _recv_bytes
    buf = self._recv(4)
          ^^^^^^^^^^^^^
  File "/home/jaansi/miniconda3/lib/python3.12/multiprocessing/connection.py", line 395, in _recv
    chunk = read(handle, remaining)
            ^^^^^^^^^^^^^^^^^^^^^^^
ConnectionResetError: [Errno 104] Connection reset by peer

During handling of the above exception, another exception occurred:

Traceback (most recent call last):
  File "/home/jaansi/miniconda3/lib/python3.12/site-packages/wandb/sdk/lib/redirect.py", line 659, in _on_write
    cb(written_data)
  File "/home/jaansi/miniconda3/lib/python3.12/site-packages/wandb/sdk/wandb_run.py", line 2302, in <lambda>
    lambda data: self._console_raw_callback("stderr", data),
                 ^^^^^^^^^^^^^^^^^^^^^^^^^^^^^^^^^^^^^^^^^^
  File "/home/jaansi/miniconda3/lib/python3.12/site-packages/wandb/sdk/wandb_run.py", line 401, in wrapper_fn
    return func(self, *args, **kwargs)
           ^^^^^^^^^^^^^^^^^^^^^^^^^^^
  File "/home/jaansi/miniconda3/lib/python3.12/site-packages/wandb/sdk/wandb_run.py", line 1444, in _console_raw_callback
    self._backend.interface.publish_output_raw(name, data)
  File "/home/jaansi/miniconda3/lib/python3.12/site-packages/wandb/sdk/interface/interface.py", line 761, in publish_output_raw
    self._publish_output_raw(o)
  File "/home/jaansi/miniconda3/lib/python3.12/site-packages/wandb/sdk/interface/interface_shared.py", line 38, in _publish_output_raw
    self._publish(rec)
  File "/home/jaansi/miniconda3/lib/python3.12/site-packages/wandb/sdk/interface/interface_sock.py", line 39, in _publish
    self._sock_client.send_record_publish(record)
  File "/home/jaansi/miniconda3/lib/python3.12/site-packages/wandb/sdk/lib/sock_client.py", line 174, in send_record_publish
    self.send_server_request(server_req)
  File "/home/jaansi/miniconda3/lib/python3.12/site-packages/wandb/sdk/lib/sock_client.py", line 154, in send_server_request
    self._send_message(msg)
  File "/home/jaansi/miniconda3/lib/python3.12/site-packages/wandb/sdk/lib/sock_client.py", line 151, in _send_message
    self._sendall_with_error_handle(header + data)
  File "/home/jaansi/miniconda3/lib/python3.12/site-packages/wandb/sdk/lib/sock_client.py", line 130, in _sendall_with_error_handle
    sent = self._sock.send(data)
           ^^^^^^^^^^^^^^^^^^^^^
BrokenPipeError: [Errno 32] Broken pipe
2025-03-18 01:24:09,476 ERROR   Thread-18 (_pin_memory_loop):1694815 [redirect.py:_on_write():661] error in stderr callback
Traceback (most recent call last):
  File "/home/jaansi/miniconda3/lib/python3.12/threading.py", line 1075, in _bootstrap_inner
    self.run()
  File "/home/jaansi/miniconda3/lib/python3.12/threading.py", line 1012, in run
    self._target(*self._args, **self._kwargs)
  File "/home/jaansi/miniconda3/lib/python3.12/site-packages/torch/utils/data/_utils/pin_memory.py", line 59, in _pin_memory_loop
    do_one_step()
  File "/home/jaansi/miniconda3/lib/python3.12/site-packages/torch/utils/data/_utils/pin_memory.py", line 35, in do_one_step
    r = in_queue.get(timeout=MP_STATUS_CHECK_INTERVAL)
        ^^^^^^^^^^^^^^^^^^^^^^^^^^^^^^^^^^^^^^^^^^^^^^
  File "/home/jaansi/miniconda3/lib/python3.12/multiprocessing/queues.py", line 122, in get
    return _ForkingPickler.loads(res)
           ^^^^^^^^^^^^^^^^^^^^^^^^^^
  File "/home/jaansi/miniconda3/lib/python3.12/site-packages/torch/multiprocessing/reductions.py", line 541, in rebuild_storage_fd
    fd = df.detach()
         ^^^^^^^^^^^
  File "/home/jaansi/miniconda3/lib/python3.12/multiprocessing/resource_sharer.py", line 57, in detach
    with _resource_sharer.get_connection(self._id) as conn:
         ^^^^^^^^^^^^^^^^^^^^^^^^^^^^^^^^^^^^^^^^^
  File "/home/jaansi/miniconda3/lib/python3.12/multiprocessing/resource_sharer.py", line 86, in get_connection
    c = Client(address, authkey=process.current_process().authkey)
        ^^^^^^^^^^^^^^^^^^^^^^^^^^^^^^^^^^^^^^^^^^^^^^^^^^^^^^^^^^
  File "/home/jaansi/miniconda3/lib/python3.12/multiprocessing/connection.py", line 525, in Client
    answer_challenge(c, authkey)
  File "/home/jaansi/miniconda3/lib/python3.12/multiprocessing/connection.py", line 953, in answer_challenge
    message = connection.recv_bytes(256)         # reject large message
              ^^^^^^^^^^^^^^^^^^^^^^^^^^
  File "/home/jaansi/miniconda3/lib/python3.12/multiprocessing/connection.py", line 216, in recv_bytes
    buf = self._recv_bytes(maxlength)
          ^^^^^^^^^^^^^^^^^^^^^^^^^^^
  File "/home/jaansi/miniconda3/lib/python3.12/multiprocessing/connection.py", line 430, in _recv_bytes
    buf = self._recv(4)
          ^^^^^^^^^^^^^
  File "/home/jaansi/miniconda3/lib/python3.12/multiprocessing/connection.py", line 395, in _recv
    chunk = read(handle, remaining)
            ^^^^^^^^^^^^^^^^^^^^^^^
ConnectionResetError: [Errno 104] Connection reset by peer

During handling of the above exception, another exception occurred:

Traceback (most recent call last):
  File "/home/jaansi/miniconda3/lib/python3.12/site-packages/wandb/sdk/lib/redirect.py", line 659, in _on_write
    cb(written_data)
  File "/home/jaansi/miniconda3/lib/python3.12/site-packages/wandb/sdk/wandb_run.py", line 2302, in <lambda>
    lambda data: self._console_raw_callback("stderr", data),
                 ^^^^^^^^^^^^^^^^^^^^^^^^^^^^^^^^^^^^^^^^^^
  File "/home/jaansi/miniconda3/lib/python3.12/site-packages/wandb/sdk/wandb_run.py", line 401, in wrapper_fn
    return func(self, *args, **kwargs)
           ^^^^^^^^^^^^^^^^^^^^^^^^^^^
  File "/home/jaansi/miniconda3/lib/python3.12/site-packages/wandb/sdk/wandb_run.py", line 1444, in _console_raw_callback
    self._backend.interface.publish_output_raw(name, data)
  File "/home/jaansi/miniconda3/lib/python3.12/site-packages/wandb/sdk/interface/interface.py", line 761, in publish_output_raw
    self._publish_output_raw(o)
  File "/home/jaansi/miniconda3/lib/python3.12/site-packages/wandb/sdk/interface/interface_shared.py", line 38, in _publish_output_raw
    self._publish(rec)
  File "/home/jaansi/miniconda3/lib/python3.12/site-packages/wandb/sdk/interface/interface_sock.py", line 39, in _publish
    self._sock_client.send_record_publish(record)
  File "/home/jaansi/miniconda3/lib/python3.12/site-packages/wandb/sdk/lib/sock_client.py", line 174, in send_record_publish
    self.send_server_request(server_req)
  File "/home/jaansi/miniconda3/lib/python3.12/site-packages/wandb/sdk/lib/sock_client.py", line 154, in send_server_request
    self._send_message(msg)
  File "/home/jaansi/miniconda3/lib/python3.12/site-packages/wandb/sdk/lib/sock_client.py", line 151, in _send_message
    self._sendall_with_error_handle(header + data)
  File "/home/jaansi/miniconda3/lib/python3.12/site-packages/wandb/sdk/lib/sock_client.py", line 130, in _sendall_with_error_handle
    sent = self._sock.send(data)
           ^^^^^^^^^^^^^^^^^^^^^
BrokenPipeError: [Errno 32] Broken pipe
2025-03-18 01:24:09,479 ERROR   Thread-18 (_pin_memory_loop):1694815 [redirect.py:_on_write():661] error in stderr callback
Traceback (most recent call last):
  File "/home/jaansi/miniconda3/lib/python3.12/threading.py", line 1075, in _bootstrap_inner
    self.run()
  File "/home/jaansi/miniconda3/lib/python3.12/threading.py", line 1012, in run
    self._target(*self._args, **self._kwargs)
  File "/home/jaansi/miniconda3/lib/python3.12/site-packages/torch/utils/data/_utils/pin_memory.py", line 59, in _pin_memory_loop
    do_one_step()
  File "/home/jaansi/miniconda3/lib/python3.12/site-packages/torch/utils/data/_utils/pin_memory.py", line 35, in do_one_step
    r = in_queue.get(timeout=MP_STATUS_CHECK_INTERVAL)
        ^^^^^^^^^^^^^^^^^^^^^^^^^^^^^^^^^^^^^^^^^^^^^^
  File "/home/jaansi/miniconda3/lib/python3.12/multiprocessing/queues.py", line 122, in get
    return _ForkingPickler.loads(res)
           ^^^^^^^^^^^^^^^^^^^^^^^^^^
  File "/home/jaansi/miniconda3/lib/python3.12/site-packages/torch/multiprocessing/reductions.py", line 541, in rebuild_storage_fd
    fd = df.detach()
         ^^^^^^^^^^^
  File "/home/jaansi/miniconda3/lib/python3.12/multiprocessing/resource_sharer.py", line 57, in detach
    with _resource_sharer.get_connection(self._id) as conn:
         ^^^^^^^^^^^^^^^^^^^^^^^^^^^^^^^^^^^^^^^^^
  File "/home/jaansi/miniconda3/lib/python3.12/multiprocessing/resource_sharer.py", line 86, in get_connection
    c = Client(address, authkey=process.current_process().authkey)
        ^^^^^^^^^^^^^^^^^^^^^^^^^^^^^^^^^^^^^^^^^^^^^^^^^^^^^^^^^^
  File "/home/jaansi/miniconda3/lib/python3.12/multiprocessing/connection.py", line 525, in Client
    answer_challenge(c, authkey)
  File "/home/jaansi/miniconda3/lib/python3.12/multiprocessing/connection.py", line 953, in answer_challenge
    message = connection.recv_bytes(256)         # reject large message
              ^^^^^^^^^^^^^^^^^^^^^^^^^^
  File "/home/jaansi/miniconda3/lib/python3.12/multiprocessing/connection.py", line 216, in recv_bytes
    buf = self._recv_bytes(maxlength)
          ^^^^^^^^^^^^^^^^^^^^^^^^^^^
  File "/home/jaansi/miniconda3/lib/python3.12/multiprocessing/connection.py", line 430, in _recv_bytes
    buf = self._recv(4)
          ^^^^^^^^^^^^^
  File "/home/jaansi/miniconda3/lib/python3.12/multiprocessing/connection.py", line 395, in _recv
    chunk = read(handle, remaining)
            ^^^^^^^^^^^^^^^^^^^^^^^
ConnectionResetError: [Errno 104] Connection reset by peer

During handling of the above exception, another exception occurred:

Traceback (most recent call last):
  File "/home/jaansi/miniconda3/lib/python3.12/site-packages/wandb/sdk/lib/redirect.py", line 659, in _on_write
    cb(written_data)
  File "/home/jaansi/miniconda3/lib/python3.12/site-packages/wandb/sdk/wandb_run.py", line 2302, in <lambda>
    lambda data: self._console_raw_callback("stderr", data),
                 ^^^^^^^^^^^^^^^^^^^^^^^^^^^^^^^^^^^^^^^^^^
  File "/home/jaansi/miniconda3/lib/python3.12/site-packages/wandb/sdk/wandb_run.py", line 401, in wrapper_fn
    return func(self, *args, **kwargs)
           ^^^^^^^^^^^^^^^^^^^^^^^^^^^
  File "/home/jaansi/miniconda3/lib/python3.12/site-packages/wandb/sdk/wandb_run.py", line 1444, in _console_raw_callback
    self._backend.interface.publish_output_raw(name, data)
  File "/home/jaansi/miniconda3/lib/python3.12/site-packages/wandb/sdk/interface/interface.py", line 761, in publish_output_raw
    self._publish_output_raw(o)
  File "/home/jaansi/miniconda3/lib/python3.12/site-packages/wandb/sdk/interface/interface_shared.py", line 38, in _publish_output_raw
    self._publish(rec)
  File "/home/jaansi/miniconda3/lib/python3.12/site-packages/wandb/sdk/interface/interface_sock.py", line 39, in _publish
    self._sock_client.send_record_publish(record)
  File "/home/jaansi/miniconda3/lib/python3.12/site-packages/wandb/sdk/lib/sock_client.py", line 174, in send_record_publish
    self.send_server_request(server_req)
  File "/home/jaansi/miniconda3/lib/python3.12/site-packages/wandb/sdk/lib/sock_client.py", line 154, in send_server_request
    self._send_message(msg)
  File "/home/jaansi/miniconda3/lib/python3.12/site-packages/wandb/sdk/lib/sock_client.py", line 151, in _send_message
    self._sendall_with_error_handle(header + data)
  File "/home/jaansi/miniconda3/lib/python3.12/site-packages/wandb/sdk/lib/sock_client.py", line 130, in _sendall_with_error_handle
    sent = self._sock.send(data)
           ^^^^^^^^^^^^^^^^^^^^^
BrokenPipeError: [Errno 32] Broken pipe
2025-03-18 01:24:09,480 ERROR   Thread-18 (_pin_memory_loop):1694815 [redirect.py:_on_write():661] error in stderr callback
Traceback (most recent call last):
  File "/home/jaansi/miniconda3/lib/python3.12/threading.py", line 1075, in _bootstrap_inner
    self.run()
  File "/home/jaansi/miniconda3/lib/python3.12/threading.py", line 1012, in run
    self._target(*self._args, **self._kwargs)
  File "/home/jaansi/miniconda3/lib/python3.12/site-packages/torch/utils/data/_utils/pin_memory.py", line 59, in _pin_memory_loop
    do_one_step()
  File "/home/jaansi/miniconda3/lib/python3.12/site-packages/torch/utils/data/_utils/pin_memory.py", line 35, in do_one_step
    r = in_queue.get(timeout=MP_STATUS_CHECK_INTERVAL)
        ^^^^^^^^^^^^^^^^^^^^^^^^^^^^^^^^^^^^^^^^^^^^^^
  File "/home/jaansi/miniconda3/lib/python3.12/multiprocessing/queues.py", line 122, in get
    return _ForkingPickler.loads(res)
           ^^^^^^^^^^^^^^^^^^^^^^^^^^
  File "/home/jaansi/miniconda3/lib/python3.12/site-packages/torch/multiprocessing/reductions.py", line 541, in rebuild_storage_fd
    fd = df.detach()
         ^^^^^^^^^^^
  File "/home/jaansi/miniconda3/lib/python3.12/multiprocessing/resource_sharer.py", line 57, in detach
    with _resource_sharer.get_connection(self._id) as conn:
         ^^^^^^^^^^^^^^^^^^^^^^^^^^^^^^^^^^^^^^^^^
  File "/home/jaansi/miniconda3/lib/python3.12/multiprocessing/resource_sharer.py", line 86, in get_connection
    c = Client(address, authkey=process.current_process().authkey)
        ^^^^^^^^^^^^^^^^^^^^^^^^^^^^^^^^^^^^^^^^^^^^^^^^^^^^^^^^^^
  File "/home/jaansi/miniconda3/lib/python3.12/multiprocessing/connection.py", line 525, in Client
    answer_challenge(c, authkey)
  File "/home/jaansi/miniconda3/lib/python3.12/multiprocessing/connection.py", line 953, in answer_challenge
    message = connection.recv_bytes(256)         # reject large message
              ^^^^^^^^^^^^^^^^^^^^^^^^^^
  File "/home/jaansi/miniconda3/lib/python3.12/multiprocessing/connection.py", line 216, in recv_bytes
    buf = self._recv_bytes(maxlength)
          ^^^^^^^^^^^^^^^^^^^^^^^^^^^
  File "/home/jaansi/miniconda3/lib/python3.12/multiprocessing/connection.py", line 430, in _recv_bytes
    buf = self._recv(4)
          ^^^^^^^^^^^^^
  File "/home/jaansi/miniconda3/lib/python3.12/multiprocessing/connection.py", line 395, in _recv
    chunk = read(handle, remaining)
            ^^^^^^^^^^^^^^^^^^^^^^^
ConnectionResetError: [Errno 104] Connection reset by peer

During handling of the above exception, another exception occurred:

Traceback (most recent call last):
  File "/home/jaansi/miniconda3/lib/python3.12/site-packages/wandb/sdk/lib/redirect.py", line 659, in _on_write
    cb(written_data)
  File "/home/jaansi/miniconda3/lib/python3.12/site-packages/wandb/sdk/wandb_run.py", line 2302, in <lambda>
    lambda data: self._console_raw_callback("stderr", data),
                 ^^^^^^^^^^^^^^^^^^^^^^^^^^^^^^^^^^^^^^^^^^
  File "/home/jaansi/miniconda3/lib/python3.12/site-packages/wandb/sdk/wandb_run.py", line 401, in wrapper_fn
    return func(self, *args, **kwargs)
           ^^^^^^^^^^^^^^^^^^^^^^^^^^^
  File "/home/jaansi/miniconda3/lib/python3.12/site-packages/wandb/sdk/wandb_run.py", line 1444, in _console_raw_callback
    self._backend.interface.publish_output_raw(name, data)
  File "/home/jaansi/miniconda3/lib/python3.12/site-packages/wandb/sdk/interface/interface.py", line 761, in publish_output_raw
    self._publish_output_raw(o)
  File "/home/jaansi/miniconda3/lib/python3.12/site-packages/wandb/sdk/interface/interface_shared.py", line 38, in _publish_output_raw
    self._publish(rec)
  File "/home/jaansi/miniconda3/lib/python3.12/site-packages/wandb/sdk/interface/interface_sock.py", line 39, in _publish
    self._sock_client.send_record_publish(record)
  File "/home/jaansi/miniconda3/lib/python3.12/site-packages/wandb/sdk/lib/sock_client.py", line 174, in send_record_publish
    self.send_server_request(server_req)
  File "/home/jaansi/miniconda3/lib/python3.12/site-packages/wandb/sdk/lib/sock_client.py", line 154, in send_server_request
    self._send_message(msg)
  File "/home/jaansi/miniconda3/lib/python3.12/site-packages/wandb/sdk/lib/sock_client.py", line 151, in _send_message
    self._sendall_with_error_handle(header + data)
  File "/home/jaansi/miniconda3/lib/python3.12/site-packages/wandb/sdk/lib/sock_client.py", line 130, in _sendall_with_error_handle
    sent = self._sock.send(data)
           ^^^^^^^^^^^^^^^^^^^^^
BrokenPipeError: [Errno 32] Broken pipe
2025-03-18 01:24:09,481 ERROR   Thread-18 (_pin_memory_loop):1694815 [redirect.py:_on_write():661] error in stderr callback
Traceback (most recent call last):
  File "/home/jaansi/miniconda3/lib/python3.12/threading.py", line 1075, in _bootstrap_inner
    self.run()
  File "/home/jaansi/miniconda3/lib/python3.12/threading.py", line 1012, in run
    self._target(*self._args, **self._kwargs)
  File "/home/jaansi/miniconda3/lib/python3.12/site-packages/torch/utils/data/_utils/pin_memory.py", line 59, in _pin_memory_loop
    do_one_step()
  File "/home/jaansi/miniconda3/lib/python3.12/site-packages/torch/utils/data/_utils/pin_memory.py", line 35, in do_one_step
    r = in_queue.get(timeout=MP_STATUS_CHECK_INTERVAL)
        ^^^^^^^^^^^^^^^^^^^^^^^^^^^^^^^^^^^^^^^^^^^^^^
  File "/home/jaansi/miniconda3/lib/python3.12/multiprocessing/queues.py", line 122, in get
    return _ForkingPickler.loads(res)
           ^^^^^^^^^^^^^^^^^^^^^^^^^^
  File "/home/jaansi/miniconda3/lib/python3.12/site-packages/torch/multiprocessing/reductions.py", line 541, in rebuild_storage_fd
    fd = df.detach()
         ^^^^^^^^^^^
  File "/home/jaansi/miniconda3/lib/python3.12/multiprocessing/resource_sharer.py", line 57, in detach
    with _resource_sharer.get_connection(self._id) as conn:
         ^^^^^^^^^^^^^^^^^^^^^^^^^^^^^^^^^^^^^^^^^
  File "/home/jaansi/miniconda3/lib/python3.12/multiprocessing/resource_sharer.py", line 86, in get_connection
    c = Client(address, authkey=process.current_process().authkey)
        ^^^^^^^^^^^^^^^^^^^^^^^^^^^^^^^^^^^^^^^^^^^^^^^^^^^^^^^^^^
  File "/home/jaansi/miniconda3/lib/python3.12/multiprocessing/connection.py", line 525, in Client
    answer_challenge(c, authkey)
  File "/home/jaansi/miniconda3/lib/python3.12/multiprocessing/connection.py", line 953, in answer_challenge
    message = connection.recv_bytes(256)         # reject large message
              ^^^^^^^^^^^^^^^^^^^^^^^^^^
  File "/home/jaansi/miniconda3/lib/python3.12/multiprocessing/connection.py", line 216, in recv_bytes
    buf = self._recv_bytes(maxlength)
          ^^^^^^^^^^^^^^^^^^^^^^^^^^^
  File "/home/jaansi/miniconda3/lib/python3.12/multiprocessing/connection.py", line 430, in _recv_bytes
    buf = self._recv(4)
          ^^^^^^^^^^^^^
  File "/home/jaansi/miniconda3/lib/python3.12/multiprocessing/connection.py", line 395, in _recv
    chunk = read(handle, remaining)
            ^^^^^^^^^^^^^^^^^^^^^^^
ConnectionResetError: [Errno 104] Connection reset by peer

During handling of the above exception, another exception occurred:

Traceback (most recent call last):
  File "/home/jaansi/miniconda3/lib/python3.12/site-packages/wandb/sdk/lib/redirect.py", line 659, in _on_write
    cb(written_data)
  File "/home/jaansi/miniconda3/lib/python3.12/site-packages/wandb/sdk/wandb_run.py", line 2302, in <lambda>
    lambda data: self._console_raw_callback("stderr", data),
                 ^^^^^^^^^^^^^^^^^^^^^^^^^^^^^^^^^^^^^^^^^^
  File "/home/jaansi/miniconda3/lib/python3.12/site-packages/wandb/sdk/wandb_run.py", line 401, in wrapper_fn
    return func(self, *args, **kwargs)
           ^^^^^^^^^^^^^^^^^^^^^^^^^^^
  File "/home/jaansi/miniconda3/lib/python3.12/site-packages/wandb/sdk/wandb_run.py", line 1444, in _console_raw_callback
    self._backend.interface.publish_output_raw(name, data)
  File "/home/jaansi/miniconda3/lib/python3.12/site-packages/wandb/sdk/interface/interface.py", line 761, in publish_output_raw
    self._publish_output_raw(o)
  File "/home/jaansi/miniconda3/lib/python3.12/site-packages/wandb/sdk/interface/interface_shared.py", line 38, in _publish_output_raw
    self._publish(rec)
  File "/home/jaansi/miniconda3/lib/python3.12/site-packages/wandb/sdk/interface/interface_sock.py", line 39, in _publish
    self._sock_client.send_record_publish(record)
  File "/home/jaansi/miniconda3/lib/python3.12/site-packages/wandb/sdk/lib/sock_client.py", line 174, in send_record_publish
    self.send_server_request(server_req)
  File "/home/jaansi/miniconda3/lib/python3.12/site-packages/wandb/sdk/lib/sock_client.py", line 154, in send_server_request
    self._send_message(msg)
  File "/home/jaansi/miniconda3/lib/python3.12/site-packages/wandb/sdk/lib/sock_client.py", line 151, in _send_message
    self._sendall_with_error_handle(header + data)
  File "/home/jaansi/miniconda3/lib/python3.12/site-packages/wandb/sdk/lib/sock_client.py", line 130, in _sendall_with_error_handle
    sent = self._sock.send(data)
           ^^^^^^^^^^^^^^^^^^^^^
BrokenPipeError: [Errno 32] Broken pipe
2025-03-18 01:24:09,482 ERROR   Thread-18 (_pin_memory_loop):1694815 [redirect.py:_on_write():661] error in stderr callback
Traceback (most recent call last):
  File "/home/jaansi/miniconda3/lib/python3.12/threading.py", line 1075, in _bootstrap_inner
    self.run()
  File "/home/jaansi/miniconda3/lib/python3.12/threading.py", line 1012, in run
    self._target(*self._args, **self._kwargs)
  File "/home/jaansi/miniconda3/lib/python3.12/site-packages/torch/utils/data/_utils/pin_memory.py", line 59, in _pin_memory_loop
    do_one_step()
  File "/home/jaansi/miniconda3/lib/python3.12/site-packages/torch/utils/data/_utils/pin_memory.py", line 35, in do_one_step
    r = in_queue.get(timeout=MP_STATUS_CHECK_INTERVAL)
        ^^^^^^^^^^^^^^^^^^^^^^^^^^^^^^^^^^^^^^^^^^^^^^
  File "/home/jaansi/miniconda3/lib/python3.12/multiprocessing/queues.py", line 122, in get
    return _ForkingPickler.loads(res)
           ^^^^^^^^^^^^^^^^^^^^^^^^^^
  File "/home/jaansi/miniconda3/lib/python3.12/site-packages/torch/multiprocessing/reductions.py", line 541, in rebuild_storage_fd
    fd = df.detach()
         ^^^^^^^^^^^
  File "/home/jaansi/miniconda3/lib/python3.12/multiprocessing/resource_sharer.py", line 57, in detach
    with _resource_sharer.get_connection(self._id) as conn:
         ^^^^^^^^^^^^^^^^^^^^^^^^^^^^^^^^^^^^^^^^^
  File "/home/jaansi/miniconda3/lib/python3.12/multiprocessing/resource_sharer.py", line 86, in get_connection
    c = Client(address, authkey=process.current_process().authkey)
        ^^^^^^^^^^^^^^^^^^^^^^^^^^^^^^^^^^^^^^^^^^^^^^^^^^^^^^^^^^
  File "/home/jaansi/miniconda3/lib/python3.12/multiprocessing/connection.py", line 525, in Client
    answer_challenge(c, authkey)
  File "/home/jaansi/miniconda3/lib/python3.12/multiprocessing/connection.py", line 953, in answer_challenge
    message = connection.recv_bytes(256)         # reject large message
              ^^^^^^^^^^^^^^^^^^^^^^^^^^
  File "/home/jaansi/miniconda3/lib/python3.12/multiprocessing/connection.py", line 216, in recv_bytes
    buf = self._recv_bytes(maxlength)
          ^^^^^^^^^^^^^^^^^^^^^^^^^^^
  File "/home/jaansi/miniconda3/lib/python3.12/multiprocessing/connection.py", line 430, in _recv_bytes
    buf = self._recv(4)
          ^^^^^^^^^^^^^
  File "/home/jaansi/miniconda3/lib/python3.12/multiprocessing/connection.py", line 395, in _recv
    chunk = read(handle, remaining)
            ^^^^^^^^^^^^^^^^^^^^^^^
ConnectionResetError: [Errno 104] Connection reset by peer

During handling of the above exception, another exception occurred:

Traceback (most recent call last):
  File "/home/jaansi/miniconda3/lib/python3.12/site-packages/wandb/sdk/lib/redirect.py", line 659, in _on_write
    cb(written_data)
  File "/home/jaansi/miniconda3/lib/python3.12/site-packages/wandb/sdk/wandb_run.py", line 2302, in <lambda>
    lambda data: self._console_raw_callback("stderr", data),
                 ^^^^^^^^^^^^^^^^^^^^^^^^^^^^^^^^^^^^^^^^^^
  File "/home/jaansi/miniconda3/lib/python3.12/site-packages/wandb/sdk/wandb_run.py", line 401, in wrapper_fn
    return func(self, *args, **kwargs)
           ^^^^^^^^^^^^^^^^^^^^^^^^^^^
  File "/home/jaansi/miniconda3/lib/python3.12/site-packages/wandb/sdk/wandb_run.py", line 1444, in _console_raw_callback
    self._backend.interface.publish_output_raw(name, data)
  File "/home/jaansi/miniconda3/lib/python3.12/site-packages/wandb/sdk/interface/interface.py", line 761, in publish_output_raw
    self._publish_output_raw(o)
  File "/home/jaansi/miniconda3/lib/python3.12/site-packages/wandb/sdk/interface/interface_shared.py", line 38, in _publish_output_raw
    self._publish(rec)
  File "/home/jaansi/miniconda3/lib/python3.12/site-packages/wandb/sdk/interface/interface_sock.py", line 39, in _publish
    self._sock_client.send_record_publish(record)
  File "/home/jaansi/miniconda3/lib/python3.12/site-packages/wandb/sdk/lib/sock_client.py", line 174, in send_record_publish
    self.send_server_request(server_req)
  File "/home/jaansi/miniconda3/lib/python3.12/site-packages/wandb/sdk/lib/sock_client.py", line 154, in send_server_request
    self._send_message(msg)
  File "/home/jaansi/miniconda3/lib/python3.12/site-packages/wandb/sdk/lib/sock_client.py", line 151, in _send_message
    self._sendall_with_error_handle(header + data)
  File "/home/jaansi/miniconda3/lib/python3.12/site-packages/wandb/sdk/lib/sock_client.py", line 130, in _sendall_with_error_handle
    sent = self._sock.send(data)
           ^^^^^^^^^^^^^^^^^^^^^
BrokenPipeError: [Errno 32] Broken pipe
2025-03-18 01:24:09,483 ERROR   Thread-18 (_pin_memory_loop):1694815 [redirect.py:_on_write():661] error in stderr callback
Traceback (most recent call last):
  File "/home/jaansi/miniconda3/lib/python3.12/threading.py", line 1075, in _bootstrap_inner
    self.run()
  File "/home/jaansi/miniconda3/lib/python3.12/threading.py", line 1012, in run
    self._target(*self._args, **self._kwargs)
  File "/home/jaansi/miniconda3/lib/python3.12/site-packages/torch/utils/data/_utils/pin_memory.py", line 59, in _pin_memory_loop
    do_one_step()
  File "/home/jaansi/miniconda3/lib/python3.12/site-packages/torch/utils/data/_utils/pin_memory.py", line 35, in do_one_step
    r = in_queue.get(timeout=MP_STATUS_CHECK_INTERVAL)
        ^^^^^^^^^^^^^^^^^^^^^^^^^^^^^^^^^^^^^^^^^^^^^^
  File "/home/jaansi/miniconda3/lib/python3.12/multiprocessing/queues.py", line 122, in get
    return _ForkingPickler.loads(res)
           ^^^^^^^^^^^^^^^^^^^^^^^^^^
  File "/home/jaansi/miniconda3/lib/python3.12/site-packages/torch/multiprocessing/reductions.py", line 541, in rebuild_storage_fd
    fd = df.detach()
         ^^^^^^^^^^^
  File "/home/jaansi/miniconda3/lib/python3.12/multiprocessing/resource_sharer.py", line 57, in detach
    with _resource_sharer.get_connection(self._id) as conn:
         ^^^^^^^^^^^^^^^^^^^^^^^^^^^^^^^^^^^^^^^^^
  File "/home/jaansi/miniconda3/lib/python3.12/multiprocessing/resource_sharer.py", line 86, in get_connection
    c = Client(address, authkey=process.current_process().authkey)
        ^^^^^^^^^^^^^^^^^^^^^^^^^^^^^^^^^^^^^^^^^^^^^^^^^^^^^^^^^^
  File "/home/jaansi/miniconda3/lib/python3.12/multiprocessing/connection.py", line 525, in Client
    answer_challenge(c, authkey)
  File "/home/jaansi/miniconda3/lib/python3.12/multiprocessing/connection.py", line 953, in answer_challenge
    message = connection.recv_bytes(256)         # reject large message
              ^^^^^^^^^^^^^^^^^^^^^^^^^^
  File "/home/jaansi/miniconda3/lib/python3.12/multiprocessing/connection.py", line 216, in recv_bytes
    buf = self._recv_bytes(maxlength)
          ^^^^^^^^^^^^^^^^^^^^^^^^^^^
  File "/home/jaansi/miniconda3/lib/python3.12/multiprocessing/connection.py", line 430, in _recv_bytes
    buf = self._recv(4)
          ^^^^^^^^^^^^^
  File "/home/jaansi/miniconda3/lib/python3.12/multiprocessing/connection.py", line 395, in _recv
    chunk = read(handle, remaining)
            ^^^^^^^^^^^^^^^^^^^^^^^
ConnectionResetError: [Errno 104] Connection reset by peer

During handling of the above exception, another exception occurred:

Traceback (most recent call last):
  File "/home/jaansi/miniconda3/lib/python3.12/site-packages/wandb/sdk/lib/redirect.py", line 659, in _on_write
    cb(written_data)
  File "/home/jaansi/miniconda3/lib/python3.12/site-packages/wandb/sdk/wandb_run.py", line 2302, in <lambda>
    lambda data: self._console_raw_callback("stderr", data),
                 ^^^^^^^^^^^^^^^^^^^^^^^^^^^^^^^^^^^^^^^^^^
  File "/home/jaansi/miniconda3/lib/python3.12/site-packages/wandb/sdk/wandb_run.py", line 401, in wrapper_fn
    return func(self, *args, **kwargs)
           ^^^^^^^^^^^^^^^^^^^^^^^^^^^
  File "/home/jaansi/miniconda3/lib/python3.12/site-packages/wandb/sdk/wandb_run.py", line 1444, in _console_raw_callback
    self._backend.interface.publish_output_raw(name, data)
  File "/home/jaansi/miniconda3/lib/python3.12/site-packages/wandb/sdk/interface/interface.py", line 761, in publish_output_raw
    self._publish_output_raw(o)
  File "/home/jaansi/miniconda3/lib/python3.12/site-packages/wandb/sdk/interface/interface_shared.py", line 38, in _publish_output_raw
    self._publish(rec)
  File "/home/jaansi/miniconda3/lib/python3.12/site-packages/wandb/sdk/interface/interface_sock.py", line 39, in _publish
    self._sock_client.send_record_publish(record)
  File "/home/jaansi/miniconda3/lib/python3.12/site-packages/wandb/sdk/lib/sock_client.py", line 174, in send_record_publish
    self.send_server_request(server_req)
  File "/home/jaansi/miniconda3/lib/python3.12/site-packages/wandb/sdk/lib/sock_client.py", line 154, in send_server_request
    self._send_message(msg)
  File "/home/jaansi/miniconda3/lib/python3.12/site-packages/wandb/sdk/lib/sock_client.py", line 151, in _send_message
    self._sendall_with_error_handle(header + data)
  File "/home/jaansi/miniconda3/lib/python3.12/site-packages/wandb/sdk/lib/sock_client.py", line 130, in _sendall_with_error_handle
    sent = self._sock.send(data)
           ^^^^^^^^^^^^^^^^^^^^^
BrokenPipeError: [Errno 32] Broken pipe
2025-03-18 01:24:09,484 ERROR   Thread-18 (_pin_memory_loop):1694815 [redirect.py:_on_write():661] error in stderr callback
Traceback (most recent call last):
  File "/home/jaansi/miniconda3/lib/python3.12/threading.py", line 1075, in _bootstrap_inner
    self.run()
  File "/home/jaansi/miniconda3/lib/python3.12/threading.py", line 1012, in run
    self._target(*self._args, **self._kwargs)
  File "/home/jaansi/miniconda3/lib/python3.12/site-packages/torch/utils/data/_utils/pin_memory.py", line 59, in _pin_memory_loop
    do_one_step()
  File "/home/jaansi/miniconda3/lib/python3.12/site-packages/torch/utils/data/_utils/pin_memory.py", line 35, in do_one_step
    r = in_queue.get(timeout=MP_STATUS_CHECK_INTERVAL)
        ^^^^^^^^^^^^^^^^^^^^^^^^^^^^^^^^^^^^^^^^^^^^^^
  File "/home/jaansi/miniconda3/lib/python3.12/multiprocessing/queues.py", line 122, in get
    return _ForkingPickler.loads(res)
           ^^^^^^^^^^^^^^^^^^^^^^^^^^
  File "/home/jaansi/miniconda3/lib/python3.12/site-packages/torch/multiprocessing/reductions.py", line 541, in rebuild_storage_fd
    fd = df.detach()
         ^^^^^^^^^^^
  File "/home/jaansi/miniconda3/lib/python3.12/multiprocessing/resource_sharer.py", line 57, in detach
    with _resource_sharer.get_connection(self._id) as conn:
         ^^^^^^^^^^^^^^^^^^^^^^^^^^^^^^^^^^^^^^^^^
  File "/home/jaansi/miniconda3/lib/python3.12/multiprocessing/resource_sharer.py", line 86, in get_connection
    c = Client(address, authkey=process.current_process().authkey)
        ^^^^^^^^^^^^^^^^^^^^^^^^^^^^^^^^^^^^^^^^^^^^^^^^^^^^^^^^^^
  File "/home/jaansi/miniconda3/lib/python3.12/multiprocessing/connection.py", line 525, in Client
    answer_challenge(c, authkey)
  File "/home/jaansi/miniconda3/lib/python3.12/multiprocessing/connection.py", line 953, in answer_challenge
    message = connection.recv_bytes(256)         # reject large message
              ^^^^^^^^^^^^^^^^^^^^^^^^^^
  File "/home/jaansi/miniconda3/lib/python3.12/multiprocessing/connection.py", line 216, in recv_bytes
    buf = self._recv_bytes(maxlength)
          ^^^^^^^^^^^^^^^^^^^^^^^^^^^
  File "/home/jaansi/miniconda3/lib/python3.12/multiprocessing/connection.py", line 430, in _recv_bytes
    buf = self._recv(4)
          ^^^^^^^^^^^^^
  File "/home/jaansi/miniconda3/lib/python3.12/multiprocessing/connection.py", line 395, in _recv
    chunk = read(handle, remaining)
            ^^^^^^^^^^^^^^^^^^^^^^^
ConnectionResetError: [Errno 104] Connection reset by peer

During handling of the above exception, another exception occurred:

Traceback (most recent call last):
  File "/home/jaansi/miniconda3/lib/python3.12/site-packages/wandb/sdk/lib/redirect.py", line 659, in _on_write
    cb(written_data)
  File "/home/jaansi/miniconda3/lib/python3.12/site-packages/wandb/sdk/wandb_run.py", line 2302, in <lambda>
    lambda data: self._console_raw_callback("stderr", data),
                 ^^^^^^^^^^^^^^^^^^^^^^^^^^^^^^^^^^^^^^^^^^
  File "/home/jaansi/miniconda3/lib/python3.12/site-packages/wandb/sdk/wandb_run.py", line 401, in wrapper_fn
    return func(self, *args, **kwargs)
           ^^^^^^^^^^^^^^^^^^^^^^^^^^^
  File "/home/jaansi/miniconda3/lib/python3.12/site-packages/wandb/sdk/wandb_run.py", line 1444, in _console_raw_callback
    self._backend.interface.publish_output_raw(name, data)
  File "/home/jaansi/miniconda3/lib/python3.12/site-packages/wandb/sdk/interface/interface.py", line 761, in publish_output_raw
    self._publish_output_raw(o)
  File "/home/jaansi/miniconda3/lib/python3.12/site-packages/wandb/sdk/interface/interface_shared.py", line 38, in _publish_output_raw
    self._publish(rec)
  File "/home/jaansi/miniconda3/lib/python3.12/site-packages/wandb/sdk/interface/interface_sock.py", line 39, in _publish
    self._sock_client.send_record_publish(record)
  File "/home/jaansi/miniconda3/lib/python3.12/site-packages/wandb/sdk/lib/sock_client.py", line 174, in send_record_publish
    self.send_server_request(server_req)
  File "/home/jaansi/miniconda3/lib/python3.12/site-packages/wandb/sdk/lib/sock_client.py", line 154, in send_server_request
    self._send_message(msg)
  File "/home/jaansi/miniconda3/lib/python3.12/site-packages/wandb/sdk/lib/sock_client.py", line 151, in _send_message
    self._sendall_with_error_handle(header + data)
  File "/home/jaansi/miniconda3/lib/python3.12/site-packages/wandb/sdk/lib/sock_client.py", line 130, in _sendall_with_error_handle
    sent = self._sock.send(data)
           ^^^^^^^^^^^^^^^^^^^^^
BrokenPipeError: [Errno 32] Broken pipe
2025-03-18 01:24:09,485 ERROR   Thread-18 (_pin_memory_loop):1694815 [redirect.py:_on_write():661] error in stderr callback
Traceback (most recent call last):
  File "/home/jaansi/miniconda3/lib/python3.12/threading.py", line 1075, in _bootstrap_inner
    self.run()
  File "/home/jaansi/miniconda3/lib/python3.12/threading.py", line 1012, in run
    self._target(*self._args, **self._kwargs)
  File "/home/jaansi/miniconda3/lib/python3.12/site-packages/torch/utils/data/_utils/pin_memory.py", line 59, in _pin_memory_loop
    do_one_step()
  File "/home/jaansi/miniconda3/lib/python3.12/site-packages/torch/utils/data/_utils/pin_memory.py", line 35, in do_one_step
    r = in_queue.get(timeout=MP_STATUS_CHECK_INTERVAL)
        ^^^^^^^^^^^^^^^^^^^^^^^^^^^^^^^^^^^^^^^^^^^^^^
  File "/home/jaansi/miniconda3/lib/python3.12/multiprocessing/queues.py", line 122, in get
    return _ForkingPickler.loads(res)
           ^^^^^^^^^^^^^^^^^^^^^^^^^^
  File "/home/jaansi/miniconda3/lib/python3.12/site-packages/torch/multiprocessing/reductions.py", line 541, in rebuild_storage_fd
    fd = df.detach()
         ^^^^^^^^^^^
  File "/home/jaansi/miniconda3/lib/python3.12/multiprocessing/resource_sharer.py", line 57, in detach
    with _resource_sharer.get_connection(self._id) as conn:
         ^^^^^^^^^^^^^^^^^^^^^^^^^^^^^^^^^^^^^^^^^
  File "/home/jaansi/miniconda3/lib/python3.12/multiprocessing/resource_sharer.py", line 86, in get_connection
    c = Client(address, authkey=process.current_process().authkey)
        ^^^^^^^^^^^^^^^^^^^^^^^^^^^^^^^^^^^^^^^^^^^^^^^^^^^^^^^^^^
  File "/home/jaansi/miniconda3/lib/python3.12/multiprocessing/connection.py", line 525, in Client
    answer_challenge(c, authkey)
  File "/home/jaansi/miniconda3/lib/python3.12/multiprocessing/connection.py", line 953, in answer_challenge
    message = connection.recv_bytes(256)         # reject large message
              ^^^^^^^^^^^^^^^^^^^^^^^^^^
  File "/home/jaansi/miniconda3/lib/python3.12/multiprocessing/connection.py", line 216, in recv_bytes
    buf = self._recv_bytes(maxlength)
          ^^^^^^^^^^^^^^^^^^^^^^^^^^^
  File "/home/jaansi/miniconda3/lib/python3.12/multiprocessing/connection.py", line 430, in _recv_bytes
    buf = self._recv(4)
          ^^^^^^^^^^^^^
  File "/home/jaansi/miniconda3/lib/python3.12/multiprocessing/connection.py", line 395, in _recv
    chunk = read(handle, remaining)
            ^^^^^^^^^^^^^^^^^^^^^^^
ConnectionResetError: [Errno 104] Connection reset by peer

During handling of the above exception, another exception occurred:

Traceback (most recent call last):
  File "/home/jaansi/miniconda3/lib/python3.12/site-packages/wandb/sdk/lib/redirect.py", line 659, in _on_write
    cb(written_data)
  File "/home/jaansi/miniconda3/lib/python3.12/site-packages/wandb/sdk/wandb_run.py", line 2302, in <lambda>
    lambda data: self._console_raw_callback("stderr", data),
                 ^^^^^^^^^^^^^^^^^^^^^^^^^^^^^^^^^^^^^^^^^^
  File "/home/jaansi/miniconda3/lib/python3.12/site-packages/wandb/sdk/wandb_run.py", line 401, in wrapper_fn
    return func(self, *args, **kwargs)
           ^^^^^^^^^^^^^^^^^^^^^^^^^^^
  File "/home/jaansi/miniconda3/lib/python3.12/site-packages/wandb/sdk/wandb_run.py", line 1444, in _console_raw_callback
    self._backend.interface.publish_output_raw(name, data)
  File "/home/jaansi/miniconda3/lib/python3.12/site-packages/wandb/sdk/interface/interface.py", line 761, in publish_output_raw
    self._publish_output_raw(o)
  File "/home/jaansi/miniconda3/lib/python3.12/site-packages/wandb/sdk/interface/interface_shared.py", line 38, in _publish_output_raw
    self._publish(rec)
  File "/home/jaansi/miniconda3/lib/python3.12/site-packages/wandb/sdk/interface/interface_sock.py", line 39, in _publish
    self._sock_client.send_record_publish(record)
  File "/home/jaansi/miniconda3/lib/python3.12/site-packages/wandb/sdk/lib/sock_client.py", line 174, in send_record_publish
    self.send_server_request(server_req)
  File "/home/jaansi/miniconda3/lib/python3.12/site-packages/wandb/sdk/lib/sock_client.py", line 154, in send_server_request
    self._send_message(msg)
  File "/home/jaansi/miniconda3/lib/python3.12/site-packages/wandb/sdk/lib/sock_client.py", line 151, in _send_message
    self._sendall_with_error_handle(header + data)
  File "/home/jaansi/miniconda3/lib/python3.12/site-packages/wandb/sdk/lib/sock_client.py", line 130, in _sendall_with_error_handle
    sent = self._sock.send(data)
           ^^^^^^^^^^^^^^^^^^^^^
BrokenPipeError: [Errno 32] Broken pipe
2025-03-18 01:24:09,486 ERROR   Thread-18 (_pin_memory_loop):1694815 [redirect.py:_on_write():661] error in stderr callback
Traceback (most recent call last):
  File "/home/jaansi/miniconda3/lib/python3.12/threading.py", line 1075, in _bootstrap_inner
    self.run()
  File "/home/jaansi/miniconda3/lib/python3.12/threading.py", line 1012, in run
    self._target(*self._args, **self._kwargs)
  File "/home/jaansi/miniconda3/lib/python3.12/site-packages/torch/utils/data/_utils/pin_memory.py", line 59, in _pin_memory_loop
    do_one_step()
  File "/home/jaansi/miniconda3/lib/python3.12/site-packages/torch/utils/data/_utils/pin_memory.py", line 35, in do_one_step
    r = in_queue.get(timeout=MP_STATUS_CHECK_INTERVAL)
        ^^^^^^^^^^^^^^^^^^^^^^^^^^^^^^^^^^^^^^^^^^^^^^
  File "/home/jaansi/miniconda3/lib/python3.12/multiprocessing/queues.py", line 122, in get
    return _ForkingPickler.loads(res)
           ^^^^^^^^^^^^^^^^^^^^^^^^^^
  File "/home/jaansi/miniconda3/lib/python3.12/site-packages/torch/multiprocessing/reductions.py", line 541, in rebuild_storage_fd
    fd = df.detach()
         ^^^^^^^^^^^
  File "/home/jaansi/miniconda3/lib/python3.12/multiprocessing/resource_sharer.py", line 57, in detach
    with _resource_sharer.get_connection(self._id) as conn:
         ^^^^^^^^^^^^^^^^^^^^^^^^^^^^^^^^^^^^^^^^^
  File "/home/jaansi/miniconda3/lib/python3.12/multiprocessing/resource_sharer.py", line 86, in get_connection
    c = Client(address, authkey=process.current_process().authkey)
        ^^^^^^^^^^^^^^^^^^^^^^^^^^^^^^^^^^^^^^^^^^^^^^^^^^^^^^^^^^
  File "/home/jaansi/miniconda3/lib/python3.12/multiprocessing/connection.py", line 525, in Client
    answer_challenge(c, authkey)
  File "/home/jaansi/miniconda3/lib/python3.12/multiprocessing/connection.py", line 953, in answer_challenge
    message = connection.recv_bytes(256)         # reject large message
              ^^^^^^^^^^^^^^^^^^^^^^^^^^
  File "/home/jaansi/miniconda3/lib/python3.12/multiprocessing/connection.py", line 216, in recv_bytes
    buf = self._recv_bytes(maxlength)
          ^^^^^^^^^^^^^^^^^^^^^^^^^^^
  File "/home/jaansi/miniconda3/lib/python3.12/multiprocessing/connection.py", line 430, in _recv_bytes
    buf = self._recv(4)
          ^^^^^^^^^^^^^
  File "/home/jaansi/miniconda3/lib/python3.12/multiprocessing/connection.py", line 395, in _recv
    chunk = read(handle, remaining)
            ^^^^^^^^^^^^^^^^^^^^^^^
ConnectionResetError: [Errno 104] Connection reset by peer

During handling of the above exception, another exception occurred:

Traceback (most recent call last):
  File "/home/jaansi/miniconda3/lib/python3.12/site-packages/wandb/sdk/lib/redirect.py", line 659, in _on_write
    cb(written_data)
  File "/home/jaansi/miniconda3/lib/python3.12/site-packages/wandb/sdk/wandb_run.py", line 2302, in <lambda>
    lambda data: self._console_raw_callback("stderr", data),
                 ^^^^^^^^^^^^^^^^^^^^^^^^^^^^^^^^^^^^^^^^^^
  File "/home/jaansi/miniconda3/lib/python3.12/site-packages/wandb/sdk/wandb_run.py", line 401, in wrapper_fn
    return func(self, *args, **kwargs)
           ^^^^^^^^^^^^^^^^^^^^^^^^^^^
  File "/home/jaansi/miniconda3/lib/python3.12/site-packages/wandb/sdk/wandb_run.py", line 1444, in _console_raw_callback
    self._backend.interface.publish_output_raw(name, data)
  File "/home/jaansi/miniconda3/lib/python3.12/site-packages/wandb/sdk/interface/interface.py", line 761, in publish_output_raw
    self._publish_output_raw(o)
  File "/home/jaansi/miniconda3/lib/python3.12/site-packages/wandb/sdk/interface/interface_shared.py", line 38, in _publish_output_raw
    self._publish(rec)
  File "/home/jaansi/miniconda3/lib/python3.12/site-packages/wandb/sdk/interface/interface_sock.py", line 39, in _publish
    self._sock_client.send_record_publish(record)
  File "/home/jaansi/miniconda3/lib/python3.12/site-packages/wandb/sdk/lib/sock_client.py", line 174, in send_record_publish
    self.send_server_request(server_req)
  File "/home/jaansi/miniconda3/lib/python3.12/site-packages/wandb/sdk/lib/sock_client.py", line 154, in send_server_request
    self._send_message(msg)
  File "/home/jaansi/miniconda3/lib/python3.12/site-packages/wandb/sdk/lib/sock_client.py", line 151, in _send_message
    self._sendall_with_error_handle(header + data)
  File "/home/jaansi/miniconda3/lib/python3.12/site-packages/wandb/sdk/lib/sock_client.py", line 130, in _sendall_with_error_handle
    sent = self._sock.send(data)
           ^^^^^^^^^^^^^^^^^^^^^
BrokenPipeError: [Errno 32] Broken pipe
2025-03-18 01:24:09,487 ERROR   Thread-18 (_pin_memory_loop):1694815 [redirect.py:_on_write():661] error in stderr callback
Traceback (most recent call last):
  File "/home/jaansi/miniconda3/lib/python3.12/threading.py", line 1075, in _bootstrap_inner
    self.run()
  File "/home/jaansi/miniconda3/lib/python3.12/threading.py", line 1012, in run
    self._target(*self._args, **self._kwargs)
  File "/home/jaansi/miniconda3/lib/python3.12/site-packages/torch/utils/data/_utils/pin_memory.py", line 59, in _pin_memory_loop
    do_one_step()
  File "/home/jaansi/miniconda3/lib/python3.12/site-packages/torch/utils/data/_utils/pin_memory.py", line 35, in do_one_step
    r = in_queue.get(timeout=MP_STATUS_CHECK_INTERVAL)
        ^^^^^^^^^^^^^^^^^^^^^^^^^^^^^^^^^^^^^^^^^^^^^^
  File "/home/jaansi/miniconda3/lib/python3.12/multiprocessing/queues.py", line 122, in get
    return _ForkingPickler.loads(res)
           ^^^^^^^^^^^^^^^^^^^^^^^^^^
  File "/home/jaansi/miniconda3/lib/python3.12/site-packages/torch/multiprocessing/reductions.py", line 541, in rebuild_storage_fd
    fd = df.detach()
         ^^^^^^^^^^^
  File "/home/jaansi/miniconda3/lib/python3.12/multiprocessing/resource_sharer.py", line 57, in detach
    with _resource_sharer.get_connection(self._id) as conn:
         ^^^^^^^^^^^^^^^^^^^^^^^^^^^^^^^^^^^^^^^^^
  File "/home/jaansi/miniconda3/lib/python3.12/multiprocessing/resource_sharer.py", line 86, in get_connection
    c = Client(address, authkey=process.current_process().authkey)
        ^^^^^^^^^^^^^^^^^^^^^^^^^^^^^^^^^^^^^^^^^^^^^^^^^^^^^^^^^^
  File "/home/jaansi/miniconda3/lib/python3.12/multiprocessing/connection.py", line 525, in Client
    answer_challenge(c, authkey)
  File "/home/jaansi/miniconda3/lib/python3.12/multiprocessing/connection.py", line 953, in answer_challenge
    message = connection.recv_bytes(256)         # reject large message
              ^^^^^^^^^^^^^^^^^^^^^^^^^^
  File "/home/jaansi/miniconda3/lib/python3.12/multiprocessing/connection.py", line 216, in recv_bytes
    buf = self._recv_bytes(maxlength)
          ^^^^^^^^^^^^^^^^^^^^^^^^^^^
  File "/home/jaansi/miniconda3/lib/python3.12/multiprocessing/connection.py", line 430, in _recv_bytes
    buf = self._recv(4)
          ^^^^^^^^^^^^^
  File "/home/jaansi/miniconda3/lib/python3.12/multiprocessing/connection.py", line 395, in _recv
    chunk = read(handle, remaining)
            ^^^^^^^^^^^^^^^^^^^^^^^
ConnectionResetError: [Errno 104] Connection reset by peer

During handling of the above exception, another exception occurred:

Traceback (most recent call last):
  File "/home/jaansi/miniconda3/lib/python3.12/site-packages/wandb/sdk/lib/redirect.py", line 659, in _on_write
    cb(written_data)
  File "/home/jaansi/miniconda3/lib/python3.12/site-packages/wandb/sdk/wandb_run.py", line 2302, in <lambda>
    lambda data: self._console_raw_callback("stderr", data),
                 ^^^^^^^^^^^^^^^^^^^^^^^^^^^^^^^^^^^^^^^^^^
  File "/home/jaansi/miniconda3/lib/python3.12/site-packages/wandb/sdk/wandb_run.py", line 401, in wrapper_fn
    return func(self, *args, **kwargs)
           ^^^^^^^^^^^^^^^^^^^^^^^^^^^
  File "/home/jaansi/miniconda3/lib/python3.12/site-packages/wandb/sdk/wandb_run.py", line 1444, in _console_raw_callback
    self._backend.interface.publish_output_raw(name, data)
  File "/home/jaansi/miniconda3/lib/python3.12/site-packages/wandb/sdk/interface/interface.py", line 761, in publish_output_raw
    self._publish_output_raw(o)
  File "/home/jaansi/miniconda3/lib/python3.12/site-packages/wandb/sdk/interface/interface_shared.py", line 38, in _publish_output_raw
    self._publish(rec)
  File "/home/jaansi/miniconda3/lib/python3.12/site-packages/wandb/sdk/interface/interface_sock.py", line 39, in _publish
    self._sock_client.send_record_publish(record)
  File "/home/jaansi/miniconda3/lib/python3.12/site-packages/wandb/sdk/lib/sock_client.py", line 174, in send_record_publish
    self.send_server_request(server_req)
  File "/home/jaansi/miniconda3/lib/python3.12/site-packages/wandb/sdk/lib/sock_client.py", line 154, in send_server_request
    self._send_message(msg)
  File "/home/jaansi/miniconda3/lib/python3.12/site-packages/wandb/sdk/lib/sock_client.py", line 151, in _send_message
    self._sendall_with_error_handle(header + data)
  File "/home/jaansi/miniconda3/lib/python3.12/site-packages/wandb/sdk/lib/sock_client.py", line 130, in _sendall_with_error_handle
    sent = self._sock.send(data)
           ^^^^^^^^^^^^^^^^^^^^^
BrokenPipeError: [Errno 32] Broken pipe
2025-03-18 01:24:09,488 ERROR   Thread-18 (_pin_memory_loop):1694815 [redirect.py:_on_write():661] error in stderr callback
Traceback (most recent call last):
  File "/home/jaansi/miniconda3/lib/python3.12/threading.py", line 1075, in _bootstrap_inner
    self.run()
  File "/home/jaansi/miniconda3/lib/python3.12/threading.py", line 1012, in run
    self._target(*self._args, **self._kwargs)
  File "/home/jaansi/miniconda3/lib/python3.12/site-packages/torch/utils/data/_utils/pin_memory.py", line 59, in _pin_memory_loop
    do_one_step()
  File "/home/jaansi/miniconda3/lib/python3.12/site-packages/torch/utils/data/_utils/pin_memory.py", line 35, in do_one_step
    r = in_queue.get(timeout=MP_STATUS_CHECK_INTERVAL)
        ^^^^^^^^^^^^^^^^^^^^^^^^^^^^^^^^^^^^^^^^^^^^^^
  File "/home/jaansi/miniconda3/lib/python3.12/multiprocessing/queues.py", line 122, in get
    return _ForkingPickler.loads(res)
           ^^^^^^^^^^^^^^^^^^^^^^^^^^
  File "/home/jaansi/miniconda3/lib/python3.12/site-packages/torch/multiprocessing/reductions.py", line 541, in rebuild_storage_fd
    fd = df.detach()
         ^^^^^^^^^^^
  File "/home/jaansi/miniconda3/lib/python3.12/multiprocessing/resource_sharer.py", line 57, in detach
    with _resource_sharer.get_connection(self._id) as conn:
         ^^^^^^^^^^^^^^^^^^^^^^^^^^^^^^^^^^^^^^^^^
  File "/home/jaansi/miniconda3/lib/python3.12/multiprocessing/resource_sharer.py", line 86, in get_connection
    c = Client(address, authkey=process.current_process().authkey)
        ^^^^^^^^^^^^^^^^^^^^^^^^^^^^^^^^^^^^^^^^^^^^^^^^^^^^^^^^^^
  File "/home/jaansi/miniconda3/lib/python3.12/multiprocessing/connection.py", line 525, in Client
    answer_challenge(c, authkey)
  File "/home/jaansi/miniconda3/lib/python3.12/multiprocessing/connection.py", line 953, in answer_challenge
    message = connection.recv_bytes(256)         # reject large message
              ^^^^^^^^^^^^^^^^^^^^^^^^^^
  File "/home/jaansi/miniconda3/lib/python3.12/multiprocessing/connection.py", line 216, in recv_bytes
    buf = self._recv_bytes(maxlength)
          ^^^^^^^^^^^^^^^^^^^^^^^^^^^
  File "/home/jaansi/miniconda3/lib/python3.12/multiprocessing/connection.py", line 430, in _recv_bytes
    buf = self._recv(4)
          ^^^^^^^^^^^^^
  File "/home/jaansi/miniconda3/lib/python3.12/multiprocessing/connection.py", line 395, in _recv
    chunk = read(handle, remaining)
            ^^^^^^^^^^^^^^^^^^^^^^^
ConnectionResetError: [Errno 104] Connection reset by peer

During handling of the above exception, another exception occurred:

Traceback (most recent call last):
  File "/home/jaansi/miniconda3/lib/python3.12/site-packages/wandb/sdk/lib/redirect.py", line 659, in _on_write
    cb(written_data)
  File "/home/jaansi/miniconda3/lib/python3.12/site-packages/wandb/sdk/wandb_run.py", line 2302, in <lambda>
    lambda data: self._console_raw_callback("stderr", data),
                 ^^^^^^^^^^^^^^^^^^^^^^^^^^^^^^^^^^^^^^^^^^
  File "/home/jaansi/miniconda3/lib/python3.12/site-packages/wandb/sdk/wandb_run.py", line 401, in wrapper_fn
    return func(self, *args, **kwargs)
           ^^^^^^^^^^^^^^^^^^^^^^^^^^^
  File "/home/jaansi/miniconda3/lib/python3.12/site-packages/wandb/sdk/wandb_run.py", line 1444, in _console_raw_callback
    self._backend.interface.publish_output_raw(name, data)
  File "/home/jaansi/miniconda3/lib/python3.12/site-packages/wandb/sdk/interface/interface.py", line 761, in publish_output_raw
    self._publish_output_raw(o)
  File "/home/jaansi/miniconda3/lib/python3.12/site-packages/wandb/sdk/interface/interface_shared.py", line 38, in _publish_output_raw
    self._publish(rec)
  File "/home/jaansi/miniconda3/lib/python3.12/site-packages/wandb/sdk/interface/interface_sock.py", line 39, in _publish
    self._sock_client.send_record_publish(record)
  File "/home/jaansi/miniconda3/lib/python3.12/site-packages/wandb/sdk/lib/sock_client.py", line 174, in send_record_publish
    self.send_server_request(server_req)
  File "/home/jaansi/miniconda3/lib/python3.12/site-packages/wandb/sdk/lib/sock_client.py", line 154, in send_server_request
    self._send_message(msg)
  File "/home/jaansi/miniconda3/lib/python3.12/site-packages/wandb/sdk/lib/sock_client.py", line 151, in _send_message
    self._sendall_with_error_handle(header + data)
  File "/home/jaansi/miniconda3/lib/python3.12/site-packages/wandb/sdk/lib/sock_client.py", line 130, in _sendall_with_error_handle
    sent = self._sock.send(data)
           ^^^^^^^^^^^^^^^^^^^^^
BrokenPipeError: [Errno 32] Broken pipe
2025-03-18 01:24:09,489 ERROR   Thread-18 (_pin_memory_loop):1694815 [redirect.py:_on_write():661] error in stderr callback
Traceback (most recent call last):
  File "/home/jaansi/miniconda3/lib/python3.12/threading.py", line 1075, in _bootstrap_inner
    self.run()
  File "/home/jaansi/miniconda3/lib/python3.12/threading.py", line 1012, in run
    self._target(*self._args, **self._kwargs)
  File "/home/jaansi/miniconda3/lib/python3.12/site-packages/torch/utils/data/_utils/pin_memory.py", line 59, in _pin_memory_loop
    do_one_step()
  File "/home/jaansi/miniconda3/lib/python3.12/site-packages/torch/utils/data/_utils/pin_memory.py", line 35, in do_one_step
    r = in_queue.get(timeout=MP_STATUS_CHECK_INTERVAL)
        ^^^^^^^^^^^^^^^^^^^^^^^^^^^^^^^^^^^^^^^^^^^^^^
  File "/home/jaansi/miniconda3/lib/python3.12/multiprocessing/queues.py", line 122, in get
    return _ForkingPickler.loads(res)
           ^^^^^^^^^^^^^^^^^^^^^^^^^^
  File "/home/jaansi/miniconda3/lib/python3.12/site-packages/torch/multiprocessing/reductions.py", line 541, in rebuild_storage_fd
    fd = df.detach()
         ^^^^^^^^^^^
  File "/home/jaansi/miniconda3/lib/python3.12/multiprocessing/resource_sharer.py", line 57, in detach
    with _resource_sharer.get_connection(self._id) as conn:
         ^^^^^^^^^^^^^^^^^^^^^^^^^^^^^^^^^^^^^^^^^
  File "/home/jaansi/miniconda3/lib/python3.12/multiprocessing/resource_sharer.py", line 86, in get_connection
    c = Client(address, authkey=process.current_process().authkey)
        ^^^^^^^^^^^^^^^^^^^^^^^^^^^^^^^^^^^^^^^^^^^^^^^^^^^^^^^^^^
  File "/home/jaansi/miniconda3/lib/python3.12/multiprocessing/connection.py", line 525, in Client
    answer_challenge(c, authkey)
  File "/home/jaansi/miniconda3/lib/python3.12/multiprocessing/connection.py", line 953, in answer_challenge
    message = connection.recv_bytes(256)         # reject large message
              ^^^^^^^^^^^^^^^^^^^^^^^^^^
  File "/home/jaansi/miniconda3/lib/python3.12/multiprocessing/connection.py", line 216, in recv_bytes
    buf = self._recv_bytes(maxlength)
          ^^^^^^^^^^^^^^^^^^^^^^^^^^^
  File "/home/jaansi/miniconda3/lib/python3.12/multiprocessing/connection.py", line 430, in _recv_bytes
    buf = self._recv(4)
          ^^^^^^^^^^^^^
  File "/home/jaansi/miniconda3/lib/python3.12/multiprocessing/connection.py", line 395, in _recv
    chunk = read(handle, remaining)
            ^^^^^^^^^^^^^^^^^^^^^^^
ConnectionResetError: [Errno 104] Connection reset by peer

During handling of the above exception, another exception occurred:

Traceback (most recent call last):
  File "/home/jaansi/miniconda3/lib/python3.12/site-packages/wandb/sdk/lib/redirect.py", line 659, in _on_write
    cb(written_data)
  File "/home/jaansi/miniconda3/lib/python3.12/site-packages/wandb/sdk/wandb_run.py", line 2302, in <lambda>
    lambda data: self._console_raw_callback("stderr", data),
                 ^^^^^^^^^^^^^^^^^^^^^^^^^^^^^^^^^^^^^^^^^^
  File "/home/jaansi/miniconda3/lib/python3.12/site-packages/wandb/sdk/wandb_run.py", line 401, in wrapper_fn
    return func(self, *args, **kwargs)
           ^^^^^^^^^^^^^^^^^^^^^^^^^^^
  File "/home/jaansi/miniconda3/lib/python3.12/site-packages/wandb/sdk/wandb_run.py", line 1444, in _console_raw_callback
    self._backend.interface.publish_output_raw(name, data)
  File "/home/jaansi/miniconda3/lib/python3.12/site-packages/wandb/sdk/interface/interface.py", line 761, in publish_output_raw
    self._publish_output_raw(o)
  File "/home/jaansi/miniconda3/lib/python3.12/site-packages/wandb/sdk/interface/interface_shared.py", line 38, in _publish_output_raw
    self._publish(rec)
  File "/home/jaansi/miniconda3/lib/python3.12/site-packages/wandb/sdk/interface/interface_sock.py", line 39, in _publish
    self._sock_client.send_record_publish(record)
  File "/home/jaansi/miniconda3/lib/python3.12/site-packages/wandb/sdk/lib/sock_client.py", line 174, in send_record_publish
    self.send_server_request(server_req)
  File "/home/jaansi/miniconda3/lib/python3.12/site-packages/wandb/sdk/lib/sock_client.py", line 154, in send_server_request
    self._send_message(msg)
  File "/home/jaansi/miniconda3/lib/python3.12/site-packages/wandb/sdk/lib/sock_client.py", line 151, in _send_message
    self._sendall_with_error_handle(header + data)
  File "/home/jaansi/miniconda3/lib/python3.12/site-packages/wandb/sdk/lib/sock_client.py", line 130, in _sendall_with_error_handle
    sent = self._sock.send(data)
           ^^^^^^^^^^^^^^^^^^^^^
BrokenPipeError: [Errno 32] Broken pipe
2025-03-18 01:24:09,490 ERROR   Thread-18 (_pin_memory_loop):1694815 [redirect.py:_on_write():661] error in stderr callback
Traceback (most recent call last):
  File "/home/jaansi/miniconda3/lib/python3.12/threading.py", line 1075, in _bootstrap_inner
    self.run()
  File "/home/jaansi/miniconda3/lib/python3.12/threading.py", line 1012, in run
    self._target(*self._args, **self._kwargs)
  File "/home/jaansi/miniconda3/lib/python3.12/site-packages/torch/utils/data/_utils/pin_memory.py", line 59, in _pin_memory_loop
    do_one_step()
  File "/home/jaansi/miniconda3/lib/python3.12/site-packages/torch/utils/data/_utils/pin_memory.py", line 35, in do_one_step
    r = in_queue.get(timeout=MP_STATUS_CHECK_INTERVAL)
        ^^^^^^^^^^^^^^^^^^^^^^^^^^^^^^^^^^^^^^^^^^^^^^
  File "/home/jaansi/miniconda3/lib/python3.12/multiprocessing/queues.py", line 122, in get
    return _ForkingPickler.loads(res)
           ^^^^^^^^^^^^^^^^^^^^^^^^^^
  File "/home/jaansi/miniconda3/lib/python3.12/site-packages/torch/multiprocessing/reductions.py", line 541, in rebuild_storage_fd
    fd = df.detach()
         ^^^^^^^^^^^
  File "/home/jaansi/miniconda3/lib/python3.12/multiprocessing/resource_sharer.py", line 57, in detach
    with _resource_sharer.get_connection(self._id) as conn:
         ^^^^^^^^^^^^^^^^^^^^^^^^^^^^^^^^^^^^^^^^^
  File "/home/jaansi/miniconda3/lib/python3.12/multiprocessing/resource_sharer.py", line 86, in get_connection
    c = Client(address, authkey=process.current_process().authkey)
        ^^^^^^^^^^^^^^^^^^^^^^^^^^^^^^^^^^^^^^^^^^^^^^^^^^^^^^^^^^
  File "/home/jaansi/miniconda3/lib/python3.12/multiprocessing/connection.py", line 525, in Client
    answer_challenge(c, authkey)
  File "/home/jaansi/miniconda3/lib/python3.12/multiprocessing/connection.py", line 953, in answer_challenge
    message = connection.recv_bytes(256)         # reject large message
              ^^^^^^^^^^^^^^^^^^^^^^^^^^
  File "/home/jaansi/miniconda3/lib/python3.12/multiprocessing/connection.py", line 216, in recv_bytes
    buf = self._recv_bytes(maxlength)
          ^^^^^^^^^^^^^^^^^^^^^^^^^^^
  File "/home/jaansi/miniconda3/lib/python3.12/multiprocessing/connection.py", line 430, in _recv_bytes
    buf = self._recv(4)
          ^^^^^^^^^^^^^
  File "/home/jaansi/miniconda3/lib/python3.12/multiprocessing/connection.py", line 395, in _recv
    chunk = read(handle, remaining)
            ^^^^^^^^^^^^^^^^^^^^^^^
ConnectionResetError: [Errno 104] Connection reset by peer

During handling of the above exception, another exception occurred:

Traceback (most recent call last):
  File "/home/jaansi/miniconda3/lib/python3.12/site-packages/wandb/sdk/lib/redirect.py", line 659, in _on_write
    cb(written_data)
  File "/home/jaansi/miniconda3/lib/python3.12/site-packages/wandb/sdk/wandb_run.py", line 2302, in <lambda>
    lambda data: self._console_raw_callback("stderr", data),
                 ^^^^^^^^^^^^^^^^^^^^^^^^^^^^^^^^^^^^^^^^^^
  File "/home/jaansi/miniconda3/lib/python3.12/site-packages/wandb/sdk/wandb_run.py", line 401, in wrapper_fn
    return func(self, *args, **kwargs)
           ^^^^^^^^^^^^^^^^^^^^^^^^^^^
  File "/home/jaansi/miniconda3/lib/python3.12/site-packages/wandb/sdk/wandb_run.py", line 1444, in _console_raw_callback
    self._backend.interface.publish_output_raw(name, data)
  File "/home/jaansi/miniconda3/lib/python3.12/site-packages/wandb/sdk/interface/interface.py", line 761, in publish_output_raw
    self._publish_output_raw(o)
  File "/home/jaansi/miniconda3/lib/python3.12/site-packages/wandb/sdk/interface/interface_shared.py", line 38, in _publish_output_raw
    self._publish(rec)
  File "/home/jaansi/miniconda3/lib/python3.12/site-packages/wandb/sdk/interface/interface_sock.py", line 39, in _publish
    self._sock_client.send_record_publish(record)
  File "/home/jaansi/miniconda3/lib/python3.12/site-packages/wandb/sdk/lib/sock_client.py", line 174, in send_record_publish
    self.send_server_request(server_req)
  File "/home/jaansi/miniconda3/lib/python3.12/site-packages/wandb/sdk/lib/sock_client.py", line 154, in send_server_request
    self._send_message(msg)
  File "/home/jaansi/miniconda3/lib/python3.12/site-packages/wandb/sdk/lib/sock_client.py", line 151, in _send_message
    self._sendall_with_error_handle(header + data)
  File "/home/jaansi/miniconda3/lib/python3.12/site-packages/wandb/sdk/lib/sock_client.py", line 130, in _sendall_with_error_handle
    sent = self._sock.send(data)
           ^^^^^^^^^^^^^^^^^^^^^
BrokenPipeError: [Errno 32] Broken pipe
2025-03-18 01:24:09,491 ERROR   Thread-18 (_pin_memory_loop):1694815 [redirect.py:_on_write():661] error in stderr callback
Traceback (most recent call last):
  File "/home/jaansi/miniconda3/lib/python3.12/threading.py", line 1075, in _bootstrap_inner
    self.run()
  File "/home/jaansi/miniconda3/lib/python3.12/threading.py", line 1012, in run
    self._target(*self._args, **self._kwargs)
  File "/home/jaansi/miniconda3/lib/python3.12/site-packages/torch/utils/data/_utils/pin_memory.py", line 59, in _pin_memory_loop
    do_one_step()
  File "/home/jaansi/miniconda3/lib/python3.12/site-packages/torch/utils/data/_utils/pin_memory.py", line 35, in do_one_step
    r = in_queue.get(timeout=MP_STATUS_CHECK_INTERVAL)
        ^^^^^^^^^^^^^^^^^^^^^^^^^^^^^^^^^^^^^^^^^^^^^^
  File "/home/jaansi/miniconda3/lib/python3.12/multiprocessing/queues.py", line 122, in get
    return _ForkingPickler.loads(res)
           ^^^^^^^^^^^^^^^^^^^^^^^^^^
  File "/home/jaansi/miniconda3/lib/python3.12/site-packages/torch/multiprocessing/reductions.py", line 541, in rebuild_storage_fd
    fd = df.detach()
         ^^^^^^^^^^^
  File "/home/jaansi/miniconda3/lib/python3.12/multiprocessing/resource_sharer.py", line 57, in detach
    with _resource_sharer.get_connection(self._id) as conn:
         ^^^^^^^^^^^^^^^^^^^^^^^^^^^^^^^^^^^^^^^^^
  File "/home/jaansi/miniconda3/lib/python3.12/multiprocessing/resource_sharer.py", line 86, in get_connection
    c = Client(address, authkey=process.current_process().authkey)
        ^^^^^^^^^^^^^^^^^^^^^^^^^^^^^^^^^^^^^^^^^^^^^^^^^^^^^^^^^^
  File "/home/jaansi/miniconda3/lib/python3.12/multiprocessing/connection.py", line 525, in Client
    answer_challenge(c, authkey)
  File "/home/jaansi/miniconda3/lib/python3.12/multiprocessing/connection.py", line 953, in answer_challenge
    message = connection.recv_bytes(256)         # reject large message
              ^^^^^^^^^^^^^^^^^^^^^^^^^^
  File "/home/jaansi/miniconda3/lib/python3.12/multiprocessing/connection.py", line 216, in recv_bytes
    buf = self._recv_bytes(maxlength)
          ^^^^^^^^^^^^^^^^^^^^^^^^^^^
  File "/home/jaansi/miniconda3/lib/python3.12/multiprocessing/connection.py", line 430, in _recv_bytes
    buf = self._recv(4)
          ^^^^^^^^^^^^^
  File "/home/jaansi/miniconda3/lib/python3.12/multiprocessing/connection.py", line 395, in _recv
    chunk = read(handle, remaining)
            ^^^^^^^^^^^^^^^^^^^^^^^
ConnectionResetError: [Errno 104] Connection reset by peer

During handling of the above exception, another exception occurred:

Traceback (most recent call last):
  File "/home/jaansi/miniconda3/lib/python3.12/site-packages/wandb/sdk/lib/redirect.py", line 659, in _on_write
    cb(written_data)
  File "/home/jaansi/miniconda3/lib/python3.12/site-packages/wandb/sdk/wandb_run.py", line 2302, in <lambda>
    lambda data: self._console_raw_callback("stderr", data),
                 ^^^^^^^^^^^^^^^^^^^^^^^^^^^^^^^^^^^^^^^^^^
  File "/home/jaansi/miniconda3/lib/python3.12/site-packages/wandb/sdk/wandb_run.py", line 401, in wrapper_fn
    return func(self, *args, **kwargs)
           ^^^^^^^^^^^^^^^^^^^^^^^^^^^
  File "/home/jaansi/miniconda3/lib/python3.12/site-packages/wandb/sdk/wandb_run.py", line 1444, in _console_raw_callback
    self._backend.interface.publish_output_raw(name, data)
  File "/home/jaansi/miniconda3/lib/python3.12/site-packages/wandb/sdk/interface/interface.py", line 761, in publish_output_raw
    self._publish_output_raw(o)
  File "/home/jaansi/miniconda3/lib/python3.12/site-packages/wandb/sdk/interface/interface_shared.py", line 38, in _publish_output_raw
    self._publish(rec)
  File "/home/jaansi/miniconda3/lib/python3.12/site-packages/wandb/sdk/interface/interface_sock.py", line 39, in _publish
    self._sock_client.send_record_publish(record)
  File "/home/jaansi/miniconda3/lib/python3.12/site-packages/wandb/sdk/lib/sock_client.py", line 174, in send_record_publish
    self.send_server_request(server_req)
  File "/home/jaansi/miniconda3/lib/python3.12/site-packages/wandb/sdk/lib/sock_client.py", line 154, in send_server_request
    self._send_message(msg)
  File "/home/jaansi/miniconda3/lib/python3.12/site-packages/wandb/sdk/lib/sock_client.py", line 151, in _send_message
    self._sendall_with_error_handle(header + data)
  File "/home/jaansi/miniconda3/lib/python3.12/site-packages/wandb/sdk/lib/sock_client.py", line 130, in _sendall_with_error_handle
    sent = self._sock.send(data)
           ^^^^^^^^^^^^^^^^^^^^^
BrokenPipeError: [Errno 32] Broken pipe
2025-03-18 01:24:09,492 ERROR   Thread-18 (_pin_memory_loop):1694815 [redirect.py:_on_write():661] error in stderr callback
Traceback (most recent call last):
  File "/home/jaansi/miniconda3/lib/python3.12/threading.py", line 1075, in _bootstrap_inner
    self.run()
  File "/home/jaansi/miniconda3/lib/python3.12/threading.py", line 1012, in run
    self._target(*self._args, **self._kwargs)
  File "/home/jaansi/miniconda3/lib/python3.12/site-packages/torch/utils/data/_utils/pin_memory.py", line 59, in _pin_memory_loop
    do_one_step()
  File "/home/jaansi/miniconda3/lib/python3.12/site-packages/torch/utils/data/_utils/pin_memory.py", line 35, in do_one_step
    r = in_queue.get(timeout=MP_STATUS_CHECK_INTERVAL)
        ^^^^^^^^^^^^^^^^^^^^^^^^^^^^^^^^^^^^^^^^^^^^^^
  File "/home/jaansi/miniconda3/lib/python3.12/multiprocessing/queues.py", line 122, in get
    return _ForkingPickler.loads(res)
           ^^^^^^^^^^^^^^^^^^^^^^^^^^
  File "/home/jaansi/miniconda3/lib/python3.12/site-packages/torch/multiprocessing/reductions.py", line 541, in rebuild_storage_fd
    fd = df.detach()
         ^^^^^^^^^^^
  File "/home/jaansi/miniconda3/lib/python3.12/multiprocessing/resource_sharer.py", line 57, in detach
    with _resource_sharer.get_connection(self._id) as conn:
         ^^^^^^^^^^^^^^^^^^^^^^^^^^^^^^^^^^^^^^^^^
  File "/home/jaansi/miniconda3/lib/python3.12/multiprocessing/resource_sharer.py", line 86, in get_connection
    c = Client(address, authkey=process.current_process().authkey)
        ^^^^^^^^^^^^^^^^^^^^^^^^^^^^^^^^^^^^^^^^^^^^^^^^^^^^^^^^^^
  File "/home/jaansi/miniconda3/lib/python3.12/multiprocessing/connection.py", line 525, in Client
    answer_challenge(c, authkey)
  File "/home/jaansi/miniconda3/lib/python3.12/multiprocessing/connection.py", line 953, in answer_challenge
    message = connection.recv_bytes(256)         # reject large message
              ^^^^^^^^^^^^^^^^^^^^^^^^^^
  File "/home/jaansi/miniconda3/lib/python3.12/multiprocessing/connection.py", line 216, in recv_bytes
    buf = self._recv_bytes(maxlength)
          ^^^^^^^^^^^^^^^^^^^^^^^^^^^
  File "/home/jaansi/miniconda3/lib/python3.12/multiprocessing/connection.py", line 430, in _recv_bytes
    buf = self._recv(4)
          ^^^^^^^^^^^^^
  File "/home/jaansi/miniconda3/lib/python3.12/multiprocessing/connection.py", line 395, in _recv
    chunk = read(handle, remaining)
            ^^^^^^^^^^^^^^^^^^^^^^^
ConnectionResetError: [Errno 104] Connection reset by peer

During handling of the above exception, another exception occurred:

Traceback (most recent call last):
  File "/home/jaansi/miniconda3/lib/python3.12/site-packages/wandb/sdk/lib/redirect.py", line 659, in _on_write
    cb(written_data)
  File "/home/jaansi/miniconda3/lib/python3.12/site-packages/wandb/sdk/wandb_run.py", line 2302, in <lambda>
    lambda data: self._console_raw_callback("stderr", data),
                 ^^^^^^^^^^^^^^^^^^^^^^^^^^^^^^^^^^^^^^^^^^
  File "/home/jaansi/miniconda3/lib/python3.12/site-packages/wandb/sdk/wandb_run.py", line 401, in wrapper_fn
    return func(self, *args, **kwargs)
           ^^^^^^^^^^^^^^^^^^^^^^^^^^^
  File "/home/jaansi/miniconda3/lib/python3.12/site-packages/wandb/sdk/wandb_run.py", line 1444, in _console_raw_callback
    self._backend.interface.publish_output_raw(name, data)
  File "/home/jaansi/miniconda3/lib/python3.12/site-packages/wandb/sdk/interface/interface.py", line 761, in publish_output_raw
    self._publish_output_raw(o)
  File "/home/jaansi/miniconda3/lib/python3.12/site-packages/wandb/sdk/interface/interface_shared.py", line 38, in _publish_output_raw
    self._publish(rec)
  File "/home/jaansi/miniconda3/lib/python3.12/site-packages/wandb/sdk/interface/interface_sock.py", line 39, in _publish
    self._sock_client.send_record_publish(record)
  File "/home/jaansi/miniconda3/lib/python3.12/site-packages/wandb/sdk/lib/sock_client.py", line 174, in send_record_publish
    self.send_server_request(server_req)
  File "/home/jaansi/miniconda3/lib/python3.12/site-packages/wandb/sdk/lib/sock_client.py", line 154, in send_server_request
    self._send_message(msg)
  File "/home/jaansi/miniconda3/lib/python3.12/site-packages/wandb/sdk/lib/sock_client.py", line 151, in _send_message
    self._sendall_with_error_handle(header + data)
  File "/home/jaansi/miniconda3/lib/python3.12/site-packages/wandb/sdk/lib/sock_client.py", line 130, in _sendall_with_error_handle
    sent = self._sock.send(data)
           ^^^^^^^^^^^^^^^^^^^^^
BrokenPipeError: [Errno 32] Broken pipe
2025-03-18 01:24:09,493 ERROR   Thread-18 (_pin_memory_loop):1694815 [redirect.py:_on_write():661] error in stderr callback
Traceback (most recent call last):
  File "/home/jaansi/miniconda3/lib/python3.12/threading.py", line 1075, in _bootstrap_inner
    self.run()
  File "/home/jaansi/miniconda3/lib/python3.12/threading.py", line 1012, in run
    self._target(*self._args, **self._kwargs)
  File "/home/jaansi/miniconda3/lib/python3.12/site-packages/torch/utils/data/_utils/pin_memory.py", line 59, in _pin_memory_loop
    do_one_step()
  File "/home/jaansi/miniconda3/lib/python3.12/site-packages/torch/utils/data/_utils/pin_memory.py", line 35, in do_one_step
    r = in_queue.get(timeout=MP_STATUS_CHECK_INTERVAL)
        ^^^^^^^^^^^^^^^^^^^^^^^^^^^^^^^^^^^^^^^^^^^^^^
  File "/home/jaansi/miniconda3/lib/python3.12/multiprocessing/queues.py", line 122, in get
    return _ForkingPickler.loads(res)
           ^^^^^^^^^^^^^^^^^^^^^^^^^^
  File "/home/jaansi/miniconda3/lib/python3.12/site-packages/torch/multiprocessing/reductions.py", line 541, in rebuild_storage_fd
    fd = df.detach()
         ^^^^^^^^^^^
  File "/home/jaansi/miniconda3/lib/python3.12/multiprocessing/resource_sharer.py", line 57, in detach
    with _resource_sharer.get_connection(self._id) as conn:
         ^^^^^^^^^^^^^^^^^^^^^^^^^^^^^^^^^^^^^^^^^
  File "/home/jaansi/miniconda3/lib/python3.12/multiprocessing/resource_sharer.py", line 86, in get_connection
    c = Client(address, authkey=process.current_process().authkey)
        ^^^^^^^^^^^^^^^^^^^^^^^^^^^^^^^^^^^^^^^^^^^^^^^^^^^^^^^^^^
  File "/home/jaansi/miniconda3/lib/python3.12/multiprocessing/connection.py", line 525, in Client
    answer_challenge(c, authkey)
  File "/home/jaansi/miniconda3/lib/python3.12/multiprocessing/connection.py", line 953, in answer_challenge
    message = connection.recv_bytes(256)         # reject large message
              ^^^^^^^^^^^^^^^^^^^^^^^^^^
  File "/home/jaansi/miniconda3/lib/python3.12/multiprocessing/connection.py", line 216, in recv_bytes
    buf = self._recv_bytes(maxlength)
          ^^^^^^^^^^^^^^^^^^^^^^^^^^^
  File "/home/jaansi/miniconda3/lib/python3.12/multiprocessing/connection.py", line 430, in _recv_bytes
    buf = self._recv(4)
          ^^^^^^^^^^^^^
  File "/home/jaansi/miniconda3/lib/python3.12/multiprocessing/connection.py", line 395, in _recv
    chunk = read(handle, remaining)
            ^^^^^^^^^^^^^^^^^^^^^^^
ConnectionResetError: [Errno 104] Connection reset by peer

During handling of the above exception, another exception occurred:

Traceback (most recent call last):
  File "/home/jaansi/miniconda3/lib/python3.12/site-packages/wandb/sdk/lib/redirect.py", line 659, in _on_write
    cb(written_data)
  File "/home/jaansi/miniconda3/lib/python3.12/site-packages/wandb/sdk/wandb_run.py", line 2302, in <lambda>
    lambda data: self._console_raw_callback("stderr", data),
                 ^^^^^^^^^^^^^^^^^^^^^^^^^^^^^^^^^^^^^^^^^^
  File "/home/jaansi/miniconda3/lib/python3.12/site-packages/wandb/sdk/wandb_run.py", line 401, in wrapper_fn
    return func(self, *args, **kwargs)
           ^^^^^^^^^^^^^^^^^^^^^^^^^^^
  File "/home/jaansi/miniconda3/lib/python3.12/site-packages/wandb/sdk/wandb_run.py", line 1444, in _console_raw_callback
    self._backend.interface.publish_output_raw(name, data)
  File "/home/jaansi/miniconda3/lib/python3.12/site-packages/wandb/sdk/interface/interface.py", line 761, in publish_output_raw
    self._publish_output_raw(o)
  File "/home/jaansi/miniconda3/lib/python3.12/site-packages/wandb/sdk/interface/interface_shared.py", line 38, in _publish_output_raw
    self._publish(rec)
  File "/home/jaansi/miniconda3/lib/python3.12/site-packages/wandb/sdk/interface/interface_sock.py", line 39, in _publish
    self._sock_client.send_record_publish(record)
  File "/home/jaansi/miniconda3/lib/python3.12/site-packages/wandb/sdk/lib/sock_client.py", line 174, in send_record_publish
    self.send_server_request(server_req)
  File "/home/jaansi/miniconda3/lib/python3.12/site-packages/wandb/sdk/lib/sock_client.py", line 154, in send_server_request
    self._send_message(msg)
  File "/home/jaansi/miniconda3/lib/python3.12/site-packages/wandb/sdk/lib/sock_client.py", line 151, in _send_message
    self._sendall_with_error_handle(header + data)
  File "/home/jaansi/miniconda3/lib/python3.12/site-packages/wandb/sdk/lib/sock_client.py", line 130, in _sendall_with_error_handle
    sent = self._sock.send(data)
           ^^^^^^^^^^^^^^^^^^^^^
BrokenPipeError: [Errno 32] Broken pipe
2025-03-18 01:24:09,494 ERROR   Thread-18 (_pin_memory_loop):1694815 [redirect.py:_on_write():661] error in stderr callback
Traceback (most recent call last):
  File "/home/jaansi/miniconda3/lib/python3.12/threading.py", line 1075, in _bootstrap_inner
    self.run()
  File "/home/jaansi/miniconda3/lib/python3.12/threading.py", line 1012, in run
    self._target(*self._args, **self._kwargs)
  File "/home/jaansi/miniconda3/lib/python3.12/site-packages/torch/utils/data/_utils/pin_memory.py", line 59, in _pin_memory_loop
    do_one_step()
  File "/home/jaansi/miniconda3/lib/python3.12/site-packages/torch/utils/data/_utils/pin_memory.py", line 35, in do_one_step
    r = in_queue.get(timeout=MP_STATUS_CHECK_INTERVAL)
        ^^^^^^^^^^^^^^^^^^^^^^^^^^^^^^^^^^^^^^^^^^^^^^
  File "/home/jaansi/miniconda3/lib/python3.12/multiprocessing/queues.py", line 122, in get
    return _ForkingPickler.loads(res)
           ^^^^^^^^^^^^^^^^^^^^^^^^^^
  File "/home/jaansi/miniconda3/lib/python3.12/site-packages/torch/multiprocessing/reductions.py", line 541, in rebuild_storage_fd
    fd = df.detach()
         ^^^^^^^^^^^
  File "/home/jaansi/miniconda3/lib/python3.12/multiprocessing/resource_sharer.py", line 57, in detach
    with _resource_sharer.get_connection(self._id) as conn:
         ^^^^^^^^^^^^^^^^^^^^^^^^^^^^^^^^^^^^^^^^^
  File "/home/jaansi/miniconda3/lib/python3.12/multiprocessing/resource_sharer.py", line 86, in get_connection
    c = Client(address, authkey=process.current_process().authkey)
        ^^^^^^^^^^^^^^^^^^^^^^^^^^^^^^^^^^^^^^^^^^^^^^^^^^^^^^^^^^
  File "/home/jaansi/miniconda3/lib/python3.12/multiprocessing/connection.py", line 525, in Client
    answer_challenge(c, authkey)
  File "/home/jaansi/miniconda3/lib/python3.12/multiprocessing/connection.py", line 953, in answer_challenge
    message = connection.recv_bytes(256)         # reject large message
              ^^^^^^^^^^^^^^^^^^^^^^^^^^
  File "/home/jaansi/miniconda3/lib/python3.12/multiprocessing/connection.py", line 216, in recv_bytes
    buf = self._recv_bytes(maxlength)
          ^^^^^^^^^^^^^^^^^^^^^^^^^^^
  File "/home/jaansi/miniconda3/lib/python3.12/multiprocessing/connection.py", line 430, in _recv_bytes
    buf = self._recv(4)
          ^^^^^^^^^^^^^
  File "/home/jaansi/miniconda3/lib/python3.12/multiprocessing/connection.py", line 395, in _recv
    chunk = read(handle, remaining)
            ^^^^^^^^^^^^^^^^^^^^^^^
ConnectionResetError: [Errno 104] Connection reset by peer

During handling of the above exception, another exception occurred:

Traceback (most recent call last):
  File "/home/jaansi/miniconda3/lib/python3.12/site-packages/wandb/sdk/lib/redirect.py", line 659, in _on_write
    cb(written_data)
  File "/home/jaansi/miniconda3/lib/python3.12/site-packages/wandb/sdk/wandb_run.py", line 2302, in <lambda>
    lambda data: self._console_raw_callback("stderr", data),
                 ^^^^^^^^^^^^^^^^^^^^^^^^^^^^^^^^^^^^^^^^^^
  File "/home/jaansi/miniconda3/lib/python3.12/site-packages/wandb/sdk/wandb_run.py", line 401, in wrapper_fn
    return func(self, *args, **kwargs)
           ^^^^^^^^^^^^^^^^^^^^^^^^^^^
  File "/home/jaansi/miniconda3/lib/python3.12/site-packages/wandb/sdk/wandb_run.py", line 1444, in _console_raw_callback
    self._backend.interface.publish_output_raw(name, data)
  File "/home/jaansi/miniconda3/lib/python3.12/site-packages/wandb/sdk/interface/interface.py", line 761, in publish_output_raw
    self._publish_output_raw(o)
  File "/home/jaansi/miniconda3/lib/python3.12/site-packages/wandb/sdk/interface/interface_shared.py", line 38, in _publish_output_raw
    self._publish(rec)
  File "/home/jaansi/miniconda3/lib/python3.12/site-packages/wandb/sdk/interface/interface_sock.py", line 39, in _publish
    self._sock_client.send_record_publish(record)
  File "/home/jaansi/miniconda3/lib/python3.12/site-packages/wandb/sdk/lib/sock_client.py", line 174, in send_record_publish
    self.send_server_request(server_req)
  File "/home/jaansi/miniconda3/lib/python3.12/site-packages/wandb/sdk/lib/sock_client.py", line 154, in send_server_request
    self._send_message(msg)
  File "/home/jaansi/miniconda3/lib/python3.12/site-packages/wandb/sdk/lib/sock_client.py", line 151, in _send_message
    self._sendall_with_error_handle(header + data)
  File "/home/jaansi/miniconda3/lib/python3.12/site-packages/wandb/sdk/lib/sock_client.py", line 130, in _sendall_with_error_handle
    sent = self._sock.send(data)
           ^^^^^^^^^^^^^^^^^^^^^
BrokenPipeError: [Errno 32] Broken pipe
2025-03-18 01:24:09,495 ERROR   Thread-18 (_pin_memory_loop):1694815 [redirect.py:_on_write():661] error in stderr callback
Traceback (most recent call last):
  File "/home/jaansi/miniconda3/lib/python3.12/threading.py", line 1075, in _bootstrap_inner
    self.run()
  File "/home/jaansi/miniconda3/lib/python3.12/threading.py", line 1012, in run
    self._target(*self._args, **self._kwargs)
  File "/home/jaansi/miniconda3/lib/python3.12/site-packages/torch/utils/data/_utils/pin_memory.py", line 59, in _pin_memory_loop
    do_one_step()
  File "/home/jaansi/miniconda3/lib/python3.12/site-packages/torch/utils/data/_utils/pin_memory.py", line 35, in do_one_step
    r = in_queue.get(timeout=MP_STATUS_CHECK_INTERVAL)
        ^^^^^^^^^^^^^^^^^^^^^^^^^^^^^^^^^^^^^^^^^^^^^^
  File "/home/jaansi/miniconda3/lib/python3.12/multiprocessing/queues.py", line 122, in get
    return _ForkingPickler.loads(res)
           ^^^^^^^^^^^^^^^^^^^^^^^^^^
  File "/home/jaansi/miniconda3/lib/python3.12/site-packages/torch/multiprocessing/reductions.py", line 541, in rebuild_storage_fd
    fd = df.detach()
         ^^^^^^^^^^^
  File "/home/jaansi/miniconda3/lib/python3.12/multiprocessing/resource_sharer.py", line 57, in detach
    with _resource_sharer.get_connection(self._id) as conn:
         ^^^^^^^^^^^^^^^^^^^^^^^^^^^^^^^^^^^^^^^^^
  File "/home/jaansi/miniconda3/lib/python3.12/multiprocessing/resource_sharer.py", line 86, in get_connection
    c = Client(address, authkey=process.current_process().authkey)
        ^^^^^^^^^^^^^^^^^^^^^^^^^^^^^^^^^^^^^^^^^^^^^^^^^^^^^^^^^^
  File "/home/jaansi/miniconda3/lib/python3.12/multiprocessing/connection.py", line 525, in Client
    answer_challenge(c, authkey)
  File "/home/jaansi/miniconda3/lib/python3.12/multiprocessing/connection.py", line 953, in answer_challenge
    message = connection.recv_bytes(256)         # reject large message
              ^^^^^^^^^^^^^^^^^^^^^^^^^^
  File "/home/jaansi/miniconda3/lib/python3.12/multiprocessing/connection.py", line 216, in recv_bytes
    buf = self._recv_bytes(maxlength)
          ^^^^^^^^^^^^^^^^^^^^^^^^^^^
  File "/home/jaansi/miniconda3/lib/python3.12/multiprocessing/connection.py", line 430, in _recv_bytes
    buf = self._recv(4)
          ^^^^^^^^^^^^^
  File "/home/jaansi/miniconda3/lib/python3.12/multiprocessing/connection.py", line 395, in _recv
    chunk = read(handle, remaining)
            ^^^^^^^^^^^^^^^^^^^^^^^
ConnectionResetError: [Errno 104] Connection reset by peer

During handling of the above exception, another exception occurred:

Traceback (most recent call last):
  File "/home/jaansi/miniconda3/lib/python3.12/site-packages/wandb/sdk/lib/redirect.py", line 659, in _on_write
    cb(written_data)
  File "/home/jaansi/miniconda3/lib/python3.12/site-packages/wandb/sdk/wandb_run.py", line 2302, in <lambda>
    lambda data: self._console_raw_callback("stderr", data),
                 ^^^^^^^^^^^^^^^^^^^^^^^^^^^^^^^^^^^^^^^^^^
  File "/home/jaansi/miniconda3/lib/python3.12/site-packages/wandb/sdk/wandb_run.py", line 401, in wrapper_fn
    return func(self, *args, **kwargs)
           ^^^^^^^^^^^^^^^^^^^^^^^^^^^
  File "/home/jaansi/miniconda3/lib/python3.12/site-packages/wandb/sdk/wandb_run.py", line 1444, in _console_raw_callback
    self._backend.interface.publish_output_raw(name, data)
  File "/home/jaansi/miniconda3/lib/python3.12/site-packages/wandb/sdk/interface/interface.py", line 761, in publish_output_raw
    self._publish_output_raw(o)
  File "/home/jaansi/miniconda3/lib/python3.12/site-packages/wandb/sdk/interface/interface_shared.py", line 38, in _publish_output_raw
    self._publish(rec)
  File "/home/jaansi/miniconda3/lib/python3.12/site-packages/wandb/sdk/interface/interface_sock.py", line 39, in _publish
    self._sock_client.send_record_publish(record)
  File "/home/jaansi/miniconda3/lib/python3.12/site-packages/wandb/sdk/lib/sock_client.py", line 174, in send_record_publish
    self.send_server_request(server_req)
  File "/home/jaansi/miniconda3/lib/python3.12/site-packages/wandb/sdk/lib/sock_client.py", line 154, in send_server_request
    self._send_message(msg)
  File "/home/jaansi/miniconda3/lib/python3.12/site-packages/wandb/sdk/lib/sock_client.py", line 151, in _send_message
    self._sendall_with_error_handle(header + data)
  File "/home/jaansi/miniconda3/lib/python3.12/site-packages/wandb/sdk/lib/sock_client.py", line 130, in _sendall_with_error_handle
    sent = self._sock.send(data)
           ^^^^^^^^^^^^^^^^^^^^^
BrokenPipeError: [Errno 32] Broken pipe
2025-03-18 01:24:09,496 ERROR   Thread-18 (_pin_memory_loop):1694815 [redirect.py:_on_write():661] error in stderr callback
Traceback (most recent call last):
  File "/home/jaansi/miniconda3/lib/python3.12/threading.py", line 1075, in _bootstrap_inner
    self.run()
  File "/home/jaansi/miniconda3/lib/python3.12/threading.py", line 1012, in run
    self._target(*self._args, **self._kwargs)
  File "/home/jaansi/miniconda3/lib/python3.12/site-packages/torch/utils/data/_utils/pin_memory.py", line 59, in _pin_memory_loop
    do_one_step()
  File "/home/jaansi/miniconda3/lib/python3.12/site-packages/torch/utils/data/_utils/pin_memory.py", line 35, in do_one_step
    r = in_queue.get(timeout=MP_STATUS_CHECK_INTERVAL)
        ^^^^^^^^^^^^^^^^^^^^^^^^^^^^^^^^^^^^^^^^^^^^^^
  File "/home/jaansi/miniconda3/lib/python3.12/multiprocessing/queues.py", line 122, in get
    return _ForkingPickler.loads(res)
           ^^^^^^^^^^^^^^^^^^^^^^^^^^
  File "/home/jaansi/miniconda3/lib/python3.12/site-packages/torch/multiprocessing/reductions.py", line 541, in rebuild_storage_fd
    fd = df.detach()
         ^^^^^^^^^^^
  File "/home/jaansi/miniconda3/lib/python3.12/multiprocessing/resource_sharer.py", line 57, in detach
    with _resource_sharer.get_connection(self._id) as conn:
         ^^^^^^^^^^^^^^^^^^^^^^^^^^^^^^^^^^^^^^^^^
  File "/home/jaansi/miniconda3/lib/python3.12/multiprocessing/resource_sharer.py", line 86, in get_connection
    c = Client(address, authkey=process.current_process().authkey)
        ^^^^^^^^^^^^^^^^^^^^^^^^^^^^^^^^^^^^^^^^^^^^^^^^^^^^^^^^^^
  File "/home/jaansi/miniconda3/lib/python3.12/multiprocessing/connection.py", line 525, in Client
    answer_challenge(c, authkey)
  File "/home/jaansi/miniconda3/lib/python3.12/multiprocessing/connection.py", line 953, in answer_challenge
    message = connection.recv_bytes(256)         # reject large message
              ^^^^^^^^^^^^^^^^^^^^^^^^^^
  File "/home/jaansi/miniconda3/lib/python3.12/multiprocessing/connection.py", line 216, in recv_bytes
    buf = self._recv_bytes(maxlength)
          ^^^^^^^^^^^^^^^^^^^^^^^^^^^
  File "/home/jaansi/miniconda3/lib/python3.12/multiprocessing/connection.py", line 430, in _recv_bytes
    buf = self._recv(4)
          ^^^^^^^^^^^^^
  File "/home/jaansi/miniconda3/lib/python3.12/multiprocessing/connection.py", line 395, in _recv
    chunk = read(handle, remaining)
            ^^^^^^^^^^^^^^^^^^^^^^^
ConnectionResetError: [Errno 104] Connection reset by peer

During handling of the above exception, another exception occurred:

Traceback (most recent call last):
  File "/home/jaansi/miniconda3/lib/python3.12/site-packages/wandb/sdk/lib/redirect.py", line 659, in _on_write
    cb(written_data)
  File "/home/jaansi/miniconda3/lib/python3.12/site-packages/wandb/sdk/wandb_run.py", line 2302, in <lambda>
    lambda data: self._console_raw_callback("stderr", data),
                 ^^^^^^^^^^^^^^^^^^^^^^^^^^^^^^^^^^^^^^^^^^
  File "/home/jaansi/miniconda3/lib/python3.12/site-packages/wandb/sdk/wandb_run.py", line 401, in wrapper_fn
    return func(self, *args, **kwargs)
           ^^^^^^^^^^^^^^^^^^^^^^^^^^^
  File "/home/jaansi/miniconda3/lib/python3.12/site-packages/wandb/sdk/wandb_run.py", line 1444, in _console_raw_callback
    self._backend.interface.publish_output_raw(name, data)
  File "/home/jaansi/miniconda3/lib/python3.12/site-packages/wandb/sdk/interface/interface.py", line 761, in publish_output_raw
    self._publish_output_raw(o)
  File "/home/jaansi/miniconda3/lib/python3.12/site-packages/wandb/sdk/interface/interface_shared.py", line 38, in _publish_output_raw
    self._publish(rec)
  File "/home/jaansi/miniconda3/lib/python3.12/site-packages/wandb/sdk/interface/interface_sock.py", line 39, in _publish
    self._sock_client.send_record_publish(record)
  File "/home/jaansi/miniconda3/lib/python3.12/site-packages/wandb/sdk/lib/sock_client.py", line 174, in send_record_publish
    self.send_server_request(server_req)
  File "/home/jaansi/miniconda3/lib/python3.12/site-packages/wandb/sdk/lib/sock_client.py", line 154, in send_server_request
    self._send_message(msg)
  File "/home/jaansi/miniconda3/lib/python3.12/site-packages/wandb/sdk/lib/sock_client.py", line 151, in _send_message
    self._sendall_with_error_handle(header + data)
  File "/home/jaansi/miniconda3/lib/python3.12/site-packages/wandb/sdk/lib/sock_client.py", line 130, in _sendall_with_error_handle
    sent = self._sock.send(data)
           ^^^^^^^^^^^^^^^^^^^^^
BrokenPipeError: [Errno 32] Broken pipe
2025-03-18 01:24:09,497 ERROR   Thread-18 (_pin_memory_loop):1694815 [redirect.py:_on_write():661] error in stderr callback
Traceback (most recent call last):
  File "/home/jaansi/miniconda3/lib/python3.12/threading.py", line 1075, in _bootstrap_inner
    self.run()
  File "/home/jaansi/miniconda3/lib/python3.12/threading.py", line 1012, in run
    self._target(*self._args, **self._kwargs)
  File "/home/jaansi/miniconda3/lib/python3.12/site-packages/torch/utils/data/_utils/pin_memory.py", line 59, in _pin_memory_loop
    do_one_step()
  File "/home/jaansi/miniconda3/lib/python3.12/site-packages/torch/utils/data/_utils/pin_memory.py", line 35, in do_one_step
    r = in_queue.get(timeout=MP_STATUS_CHECK_INTERVAL)
        ^^^^^^^^^^^^^^^^^^^^^^^^^^^^^^^^^^^^^^^^^^^^^^
  File "/home/jaansi/miniconda3/lib/python3.12/multiprocessing/queues.py", line 122, in get
    return _ForkingPickler.loads(res)
           ^^^^^^^^^^^^^^^^^^^^^^^^^^
  File "/home/jaansi/miniconda3/lib/python3.12/site-packages/torch/multiprocessing/reductions.py", line 541, in rebuild_storage_fd
    fd = df.detach()
         ^^^^^^^^^^^
  File "/home/jaansi/miniconda3/lib/python3.12/multiprocessing/resource_sharer.py", line 57, in detach
    with _resource_sharer.get_connection(self._id) as conn:
         ^^^^^^^^^^^^^^^^^^^^^^^^^^^^^^^^^^^^^^^^^
  File "/home/jaansi/miniconda3/lib/python3.12/multiprocessing/resource_sharer.py", line 86, in get_connection
    c = Client(address, authkey=process.current_process().authkey)
        ^^^^^^^^^^^^^^^^^^^^^^^^^^^^^^^^^^^^^^^^^^^^^^^^^^^^^^^^^^
  File "/home/jaansi/miniconda3/lib/python3.12/multiprocessing/connection.py", line 525, in Client
    answer_challenge(c, authkey)
  File "/home/jaansi/miniconda3/lib/python3.12/multiprocessing/connection.py", line 953, in answer_challenge
    message = connection.recv_bytes(256)         # reject large message
              ^^^^^^^^^^^^^^^^^^^^^^^^^^
  File "/home/jaansi/miniconda3/lib/python3.12/multiprocessing/connection.py", line 216, in recv_bytes
    buf = self._recv_bytes(maxlength)
          ^^^^^^^^^^^^^^^^^^^^^^^^^^^
  File "/home/jaansi/miniconda3/lib/python3.12/multiprocessing/connection.py", line 430, in _recv_bytes
    buf = self._recv(4)
          ^^^^^^^^^^^^^
  File "/home/jaansi/miniconda3/lib/python3.12/multiprocessing/connection.py", line 395, in _recv
    chunk = read(handle, remaining)
            ^^^^^^^^^^^^^^^^^^^^^^^
ConnectionResetError: [Errno 104] Connection reset by peer

During handling of the above exception, another exception occurred:

Traceback (most recent call last):
  File "/home/jaansi/miniconda3/lib/python3.12/site-packages/wandb/sdk/lib/redirect.py", line 659, in _on_write
    cb(written_data)
  File "/home/jaansi/miniconda3/lib/python3.12/site-packages/wandb/sdk/wandb_run.py", line 2302, in <lambda>
    lambda data: self._console_raw_callback("stderr", data),
                 ^^^^^^^^^^^^^^^^^^^^^^^^^^^^^^^^^^^^^^^^^^
  File "/home/jaansi/miniconda3/lib/python3.12/site-packages/wandb/sdk/wandb_run.py", line 401, in wrapper_fn
    return func(self, *args, **kwargs)
           ^^^^^^^^^^^^^^^^^^^^^^^^^^^
  File "/home/jaansi/miniconda3/lib/python3.12/site-packages/wandb/sdk/wandb_run.py", line 1444, in _console_raw_callback
    self._backend.interface.publish_output_raw(name, data)
  File "/home/jaansi/miniconda3/lib/python3.12/site-packages/wandb/sdk/interface/interface.py", line 761, in publish_output_raw
    self._publish_output_raw(o)
  File "/home/jaansi/miniconda3/lib/python3.12/site-packages/wandb/sdk/interface/interface_shared.py", line 38, in _publish_output_raw
    self._publish(rec)
  File "/home/jaansi/miniconda3/lib/python3.12/site-packages/wandb/sdk/interface/interface_sock.py", line 39, in _publish
    self._sock_client.send_record_publish(record)
  File "/home/jaansi/miniconda3/lib/python3.12/site-packages/wandb/sdk/lib/sock_client.py", line 174, in send_record_publish
    self.send_server_request(server_req)
  File "/home/jaansi/miniconda3/lib/python3.12/site-packages/wandb/sdk/lib/sock_client.py", line 154, in send_server_request
    self._send_message(msg)
  File "/home/jaansi/miniconda3/lib/python3.12/site-packages/wandb/sdk/lib/sock_client.py", line 151, in _send_message
    self._sendall_with_error_handle(header + data)
  File "/home/jaansi/miniconda3/lib/python3.12/site-packages/wandb/sdk/lib/sock_client.py", line 130, in _sendall_with_error_handle
    sent = self._sock.send(data)
           ^^^^^^^^^^^^^^^^^^^^^
BrokenPipeError: [Errno 32] Broken pipe
2025-03-18 01:24:09,499 ERROR   Thread-18 (_pin_memory_loop):1694815 [redirect.py:_on_write():661] error in stderr callback
Traceback (most recent call last):
  File "/home/jaansi/miniconda3/lib/python3.12/threading.py", line 1075, in _bootstrap_inner
    self.run()
  File "/home/jaansi/miniconda3/lib/python3.12/threading.py", line 1012, in run
    self._target(*self._args, **self._kwargs)
  File "/home/jaansi/miniconda3/lib/python3.12/site-packages/torch/utils/data/_utils/pin_memory.py", line 59, in _pin_memory_loop
    do_one_step()
  File "/home/jaansi/miniconda3/lib/python3.12/site-packages/torch/utils/data/_utils/pin_memory.py", line 35, in do_one_step
    r = in_queue.get(timeout=MP_STATUS_CHECK_INTERVAL)
        ^^^^^^^^^^^^^^^^^^^^^^^^^^^^^^^^^^^^^^^^^^^^^^
  File "/home/jaansi/miniconda3/lib/python3.12/multiprocessing/queues.py", line 122, in get
    return _ForkingPickler.loads(res)
           ^^^^^^^^^^^^^^^^^^^^^^^^^^
  File "/home/jaansi/miniconda3/lib/python3.12/site-packages/torch/multiprocessing/reductions.py", line 541, in rebuild_storage_fd
    fd = df.detach()
         ^^^^^^^^^^^
  File "/home/jaansi/miniconda3/lib/python3.12/multiprocessing/resource_sharer.py", line 57, in detach
    with _resource_sharer.get_connection(self._id) as conn:
         ^^^^^^^^^^^^^^^^^^^^^^^^^^^^^^^^^^^^^^^^^
  File "/home/jaansi/miniconda3/lib/python3.12/multiprocessing/resource_sharer.py", line 86, in get_connection
    c = Client(address, authkey=process.current_process().authkey)
        ^^^^^^^^^^^^^^^^^^^^^^^^^^^^^^^^^^^^^^^^^^^^^^^^^^^^^^^^^^
  File "/home/jaansi/miniconda3/lib/python3.12/multiprocessing/connection.py", line 525, in Client
    answer_challenge(c, authkey)
  File "/home/jaansi/miniconda3/lib/python3.12/multiprocessing/connection.py", line 953, in answer_challenge
    message = connection.recv_bytes(256)         # reject large message
              ^^^^^^^^^^^^^^^^^^^^^^^^^^
  File "/home/jaansi/miniconda3/lib/python3.12/multiprocessing/connection.py", line 216, in recv_bytes
    buf = self._recv_bytes(maxlength)
          ^^^^^^^^^^^^^^^^^^^^^^^^^^^
  File "/home/jaansi/miniconda3/lib/python3.12/multiprocessing/connection.py", line 430, in _recv_bytes
    buf = self._recv(4)
          ^^^^^^^^^^^^^
  File "/home/jaansi/miniconda3/lib/python3.12/multiprocessing/connection.py", line 395, in _recv
    chunk = read(handle, remaining)
            ^^^^^^^^^^^^^^^^^^^^^^^
ConnectionResetError: [Errno 104] Connection reset by peer

During handling of the above exception, another exception occurred:

Traceback (most recent call last):
  File "/home/jaansi/miniconda3/lib/python3.12/site-packages/wandb/sdk/lib/redirect.py", line 659, in _on_write
    cb(written_data)
  File "/home/jaansi/miniconda3/lib/python3.12/site-packages/wandb/sdk/wandb_run.py", line 2302, in <lambda>
    lambda data: self._console_raw_callback("stderr", data),
                 ^^^^^^^^^^^^^^^^^^^^^^^^^^^^^^^^^^^^^^^^^^
  File "/home/jaansi/miniconda3/lib/python3.12/site-packages/wandb/sdk/wandb_run.py", line 401, in wrapper_fn
    return func(self, *args, **kwargs)
           ^^^^^^^^^^^^^^^^^^^^^^^^^^^
  File "/home/jaansi/miniconda3/lib/python3.12/site-packages/wandb/sdk/wandb_run.py", line 1444, in _console_raw_callback
    self._backend.interface.publish_output_raw(name, data)
  File "/home/jaansi/miniconda3/lib/python3.12/site-packages/wandb/sdk/interface/interface.py", line 761, in publish_output_raw
    self._publish_output_raw(o)
  File "/home/jaansi/miniconda3/lib/python3.12/site-packages/wandb/sdk/interface/interface_shared.py", line 38, in _publish_output_raw
    self._publish(rec)
  File "/home/jaansi/miniconda3/lib/python3.12/site-packages/wandb/sdk/interface/interface_sock.py", line 39, in _publish
    self._sock_client.send_record_publish(record)
  File "/home/jaansi/miniconda3/lib/python3.12/site-packages/wandb/sdk/lib/sock_client.py", line 174, in send_record_publish
    self.send_server_request(server_req)
  File "/home/jaansi/miniconda3/lib/python3.12/site-packages/wandb/sdk/lib/sock_client.py", line 154, in send_server_request
    self._send_message(msg)
  File "/home/jaansi/miniconda3/lib/python3.12/site-packages/wandb/sdk/lib/sock_client.py", line 151, in _send_message
    self._sendall_with_error_handle(header + data)
  File "/home/jaansi/miniconda3/lib/python3.12/site-packages/wandb/sdk/lib/sock_client.py", line 130, in _sendall_with_error_handle
    sent = self._sock.send(data)
           ^^^^^^^^^^^^^^^^^^^^^
BrokenPipeError: [Errno 32] Broken pipe
2025-03-18 01:24:09,500 ERROR   Thread-18 (_pin_memory_loop):1694815 [redirect.py:_on_write():661] error in stderr callback
Traceback (most recent call last):
  File "/home/jaansi/miniconda3/lib/python3.12/threading.py", line 1075, in _bootstrap_inner
    self.run()
  File "/home/jaansi/miniconda3/lib/python3.12/threading.py", line 1012, in run
    self._target(*self._args, **self._kwargs)
  File "/home/jaansi/miniconda3/lib/python3.12/site-packages/torch/utils/data/_utils/pin_memory.py", line 59, in _pin_memory_loop
    do_one_step()
  File "/home/jaansi/miniconda3/lib/python3.12/site-packages/torch/utils/data/_utils/pin_memory.py", line 35, in do_one_step
    r = in_queue.get(timeout=MP_STATUS_CHECK_INTERVAL)
        ^^^^^^^^^^^^^^^^^^^^^^^^^^^^^^^^^^^^^^^^^^^^^^
  File "/home/jaansi/miniconda3/lib/python3.12/multiprocessing/queues.py", line 122, in get
    return _ForkingPickler.loads(res)
           ^^^^^^^^^^^^^^^^^^^^^^^^^^
  File "/home/jaansi/miniconda3/lib/python3.12/site-packages/torch/multiprocessing/reductions.py", line 541, in rebuild_storage_fd
    fd = df.detach()
         ^^^^^^^^^^^
  File "/home/jaansi/miniconda3/lib/python3.12/multiprocessing/resource_sharer.py", line 57, in detach
    with _resource_sharer.get_connection(self._id) as conn:
         ^^^^^^^^^^^^^^^^^^^^^^^^^^^^^^^^^^^^^^^^^
  File "/home/jaansi/miniconda3/lib/python3.12/multiprocessing/resource_sharer.py", line 86, in get_connection
    c = Client(address, authkey=process.current_process().authkey)
        ^^^^^^^^^^^^^^^^^^^^^^^^^^^^^^^^^^^^^^^^^^^^^^^^^^^^^^^^^^
  File "/home/jaansi/miniconda3/lib/python3.12/multiprocessing/connection.py", line 525, in Client
    answer_challenge(c, authkey)
  File "/home/jaansi/miniconda3/lib/python3.12/multiprocessing/connection.py", line 953, in answer_challenge
    message = connection.recv_bytes(256)         # reject large message
              ^^^^^^^^^^^^^^^^^^^^^^^^^^
  File "/home/jaansi/miniconda3/lib/python3.12/multiprocessing/connection.py", line 216, in recv_bytes
    buf = self._recv_bytes(maxlength)
          ^^^^^^^^^^^^^^^^^^^^^^^^^^^
  File "/home/jaansi/miniconda3/lib/python3.12/multiprocessing/connection.py", line 430, in _recv_bytes
    buf = self._recv(4)
          ^^^^^^^^^^^^^
  File "/home/jaansi/miniconda3/lib/python3.12/multiprocessing/connection.py", line 395, in _recv
    chunk = read(handle, remaining)
            ^^^^^^^^^^^^^^^^^^^^^^^
ConnectionResetError: [Errno 104] Connection reset by peer

During handling of the above exception, another exception occurred:

Traceback (most recent call last):
  File "/home/jaansi/miniconda3/lib/python3.12/site-packages/wandb/sdk/lib/redirect.py", line 659, in _on_write
    cb(written_data)
  File "/home/jaansi/miniconda3/lib/python3.12/site-packages/wandb/sdk/wandb_run.py", line 2302, in <lambda>
    lambda data: self._console_raw_callback("stderr", data),
                 ^^^^^^^^^^^^^^^^^^^^^^^^^^^^^^^^^^^^^^^^^^
  File "/home/jaansi/miniconda3/lib/python3.12/site-packages/wandb/sdk/wandb_run.py", line 401, in wrapper_fn
    return func(self, *args, **kwargs)
           ^^^^^^^^^^^^^^^^^^^^^^^^^^^
  File "/home/jaansi/miniconda3/lib/python3.12/site-packages/wandb/sdk/wandb_run.py", line 1444, in _console_raw_callback
    self._backend.interface.publish_output_raw(name, data)
  File "/home/jaansi/miniconda3/lib/python3.12/site-packages/wandb/sdk/interface/interface.py", line 761, in publish_output_raw
    self._publish_output_raw(o)
  File "/home/jaansi/miniconda3/lib/python3.12/site-packages/wandb/sdk/interface/interface_shared.py", line 38, in _publish_output_raw
    self._publish(rec)
  File "/home/jaansi/miniconda3/lib/python3.12/site-packages/wandb/sdk/interface/interface_sock.py", line 39, in _publish
    self._sock_client.send_record_publish(record)
  File "/home/jaansi/miniconda3/lib/python3.12/site-packages/wandb/sdk/lib/sock_client.py", line 174, in send_record_publish
    self.send_server_request(server_req)
  File "/home/jaansi/miniconda3/lib/python3.12/site-packages/wandb/sdk/lib/sock_client.py", line 154, in send_server_request
    self._send_message(msg)
  File "/home/jaansi/miniconda3/lib/python3.12/site-packages/wandb/sdk/lib/sock_client.py", line 151, in _send_message
    self._sendall_with_error_handle(header + data)
  File "/home/jaansi/miniconda3/lib/python3.12/site-packages/wandb/sdk/lib/sock_client.py", line 130, in _sendall_with_error_handle
    sent = self._sock.send(data)
           ^^^^^^^^^^^^^^^^^^^^^
BrokenPipeError: [Errno 32] Broken pipe
2025-03-18 01:24:09,501 ERROR   Thread-18 (_pin_memory_loop):1694815 [redirect.py:_on_write():661] error in stderr callback
Traceback (most recent call last):
  File "/home/jaansi/miniconda3/lib/python3.12/threading.py", line 1075, in _bootstrap_inner
    self.run()
  File "/home/jaansi/miniconda3/lib/python3.12/threading.py", line 1012, in run
    self._target(*self._args, **self._kwargs)
  File "/home/jaansi/miniconda3/lib/python3.12/site-packages/torch/utils/data/_utils/pin_memory.py", line 59, in _pin_memory_loop
    do_one_step()
  File "/home/jaansi/miniconda3/lib/python3.12/site-packages/torch/utils/data/_utils/pin_memory.py", line 35, in do_one_step
    r = in_queue.get(timeout=MP_STATUS_CHECK_INTERVAL)
        ^^^^^^^^^^^^^^^^^^^^^^^^^^^^^^^^^^^^^^^^^^^^^^
  File "/home/jaansi/miniconda3/lib/python3.12/multiprocessing/queues.py", line 122, in get
    return _ForkingPickler.loads(res)
           ^^^^^^^^^^^^^^^^^^^^^^^^^^
  File "/home/jaansi/miniconda3/lib/python3.12/site-packages/torch/multiprocessing/reductions.py", line 541, in rebuild_storage_fd
    fd = df.detach()
         ^^^^^^^^^^^
  File "/home/jaansi/miniconda3/lib/python3.12/multiprocessing/resource_sharer.py", line 57, in detach
    with _resource_sharer.get_connection(self._id) as conn:
         ^^^^^^^^^^^^^^^^^^^^^^^^^^^^^^^^^^^^^^^^^
  File "/home/jaansi/miniconda3/lib/python3.12/multiprocessing/resource_sharer.py", line 86, in get_connection
    c = Client(address, authkey=process.current_process().authkey)
        ^^^^^^^^^^^^^^^^^^^^^^^^^^^^^^^^^^^^^^^^^^^^^^^^^^^^^^^^^^
  File "/home/jaansi/miniconda3/lib/python3.12/multiprocessing/connection.py", line 525, in Client
    answer_challenge(c, authkey)
  File "/home/jaansi/miniconda3/lib/python3.12/multiprocessing/connection.py", line 953, in answer_challenge
    message = connection.recv_bytes(256)         # reject large message
              ^^^^^^^^^^^^^^^^^^^^^^^^^^
  File "/home/jaansi/miniconda3/lib/python3.12/multiprocessing/connection.py", line 216, in recv_bytes
    buf = self._recv_bytes(maxlength)
          ^^^^^^^^^^^^^^^^^^^^^^^^^^^
  File "/home/jaansi/miniconda3/lib/python3.12/multiprocessing/connection.py", line 430, in _recv_bytes
    buf = self._recv(4)
          ^^^^^^^^^^^^^
  File "/home/jaansi/miniconda3/lib/python3.12/multiprocessing/connection.py", line 395, in _recv
    chunk = read(handle, remaining)
            ^^^^^^^^^^^^^^^^^^^^^^^
ConnectionResetError: [Errno 104] Connection reset by peer

During handling of the above exception, another exception occurred:

Traceback (most recent call last):
  File "/home/jaansi/miniconda3/lib/python3.12/site-packages/wandb/sdk/lib/redirect.py", line 659, in _on_write
    cb(written_data)
  File "/home/jaansi/miniconda3/lib/python3.12/site-packages/wandb/sdk/wandb_run.py", line 2302, in <lambda>
    lambda data: self._console_raw_callback("stderr", data),
                 ^^^^^^^^^^^^^^^^^^^^^^^^^^^^^^^^^^^^^^^^^^
  File "/home/jaansi/miniconda3/lib/python3.12/site-packages/wandb/sdk/wandb_run.py", line 401, in wrapper_fn
    return func(self, *args, **kwargs)
           ^^^^^^^^^^^^^^^^^^^^^^^^^^^
  File "/home/jaansi/miniconda3/lib/python3.12/site-packages/wandb/sdk/wandb_run.py", line 1444, in _console_raw_callback
    self._backend.interface.publish_output_raw(name, data)
  File "/home/jaansi/miniconda3/lib/python3.12/site-packages/wandb/sdk/interface/interface.py", line 761, in publish_output_raw
    self._publish_output_raw(o)
  File "/home/jaansi/miniconda3/lib/python3.12/site-packages/wandb/sdk/interface/interface_shared.py", line 38, in _publish_output_raw
    self._publish(rec)
  File "/home/jaansi/miniconda3/lib/python3.12/site-packages/wandb/sdk/interface/interface_sock.py", line 39, in _publish
    self._sock_client.send_record_publish(record)
  File "/home/jaansi/miniconda3/lib/python3.12/site-packages/wandb/sdk/lib/sock_client.py", line 174, in send_record_publish
    self.send_server_request(server_req)
  File "/home/jaansi/miniconda3/lib/python3.12/site-packages/wandb/sdk/lib/sock_client.py", line 154, in send_server_request
    self._send_message(msg)
  File "/home/jaansi/miniconda3/lib/python3.12/site-packages/wandb/sdk/lib/sock_client.py", line 151, in _send_message
    self._sendall_with_error_handle(header + data)
  File "/home/jaansi/miniconda3/lib/python3.12/site-packages/wandb/sdk/lib/sock_client.py", line 130, in _sendall_with_error_handle
    sent = self._sock.send(data)
           ^^^^^^^^^^^^^^^^^^^^^
BrokenPipeError: [Errno 32] Broken pipe
2025-03-18 01:24:09,502 ERROR   Thread-18 (_pin_memory_loop):1694815 [redirect.py:_on_write():661] error in stderr callback
Traceback (most recent call last):
  File "/home/jaansi/miniconda3/lib/python3.12/threading.py", line 1075, in _bootstrap_inner
    self.run()
  File "/home/jaansi/miniconda3/lib/python3.12/threading.py", line 1012, in run
    self._target(*self._args, **self._kwargs)
  File "/home/jaansi/miniconda3/lib/python3.12/site-packages/torch/utils/data/_utils/pin_memory.py", line 59, in _pin_memory_loop
    do_one_step()
  File "/home/jaansi/miniconda3/lib/python3.12/site-packages/torch/utils/data/_utils/pin_memory.py", line 35, in do_one_step
    r = in_queue.get(timeout=MP_STATUS_CHECK_INTERVAL)
        ^^^^^^^^^^^^^^^^^^^^^^^^^^^^^^^^^^^^^^^^^^^^^^
  File "/home/jaansi/miniconda3/lib/python3.12/multiprocessing/queues.py", line 122, in get
    return _ForkingPickler.loads(res)
           ^^^^^^^^^^^^^^^^^^^^^^^^^^
  File "/home/jaansi/miniconda3/lib/python3.12/site-packages/torch/multiprocessing/reductions.py", line 541, in rebuild_storage_fd
    fd = df.detach()
         ^^^^^^^^^^^
  File "/home/jaansi/miniconda3/lib/python3.12/multiprocessing/resource_sharer.py", line 57, in detach
    with _resource_sharer.get_connection(self._id) as conn:
         ^^^^^^^^^^^^^^^^^^^^^^^^^^^^^^^^^^^^^^^^^
  File "/home/jaansi/miniconda3/lib/python3.12/multiprocessing/resource_sharer.py", line 86, in get_connection
    c = Client(address, authkey=process.current_process().authkey)
        ^^^^^^^^^^^^^^^^^^^^^^^^^^^^^^^^^^^^^^^^^^^^^^^^^^^^^^^^^^
  File "/home/jaansi/miniconda3/lib/python3.12/multiprocessing/connection.py", line 525, in Client
    answer_challenge(c, authkey)
  File "/home/jaansi/miniconda3/lib/python3.12/multiprocessing/connection.py", line 953, in answer_challenge
    message = connection.recv_bytes(256)         # reject large message
              ^^^^^^^^^^^^^^^^^^^^^^^^^^
  File "/home/jaansi/miniconda3/lib/python3.12/multiprocessing/connection.py", line 216, in recv_bytes
    buf = self._recv_bytes(maxlength)
          ^^^^^^^^^^^^^^^^^^^^^^^^^^^
  File "/home/jaansi/miniconda3/lib/python3.12/multiprocessing/connection.py", line 430, in _recv_bytes
    buf = self._recv(4)
          ^^^^^^^^^^^^^
  File "/home/jaansi/miniconda3/lib/python3.12/multiprocessing/connection.py", line 395, in _recv
    chunk = read(handle, remaining)
            ^^^^^^^^^^^^^^^^^^^^^^^
ConnectionResetError: [Errno 104] Connection reset by peer

During handling of the above exception, another exception occurred:

Traceback (most recent call last):
  File "/home/jaansi/miniconda3/lib/python3.12/site-packages/wandb/sdk/lib/redirect.py", line 659, in _on_write
    cb(written_data)
  File "/home/jaansi/miniconda3/lib/python3.12/site-packages/wandb/sdk/wandb_run.py", line 2302, in <lambda>
    lambda data: self._console_raw_callback("stderr", data),
                 ^^^^^^^^^^^^^^^^^^^^^^^^^^^^^^^^^^^^^^^^^^
  File "/home/jaansi/miniconda3/lib/python3.12/site-packages/wandb/sdk/wandb_run.py", line 401, in wrapper_fn
    return func(self, *args, **kwargs)
           ^^^^^^^^^^^^^^^^^^^^^^^^^^^
  File "/home/jaansi/miniconda3/lib/python3.12/site-packages/wandb/sdk/wandb_run.py", line 1444, in _console_raw_callback
    self._backend.interface.publish_output_raw(name, data)
  File "/home/jaansi/miniconda3/lib/python3.12/site-packages/wandb/sdk/interface/interface.py", line 761, in publish_output_raw
    self._publish_output_raw(o)
  File "/home/jaansi/miniconda3/lib/python3.12/site-packages/wandb/sdk/interface/interface_shared.py", line 38, in _publish_output_raw
    self._publish(rec)
  File "/home/jaansi/miniconda3/lib/python3.12/site-packages/wandb/sdk/interface/interface_sock.py", line 39, in _publish
    self._sock_client.send_record_publish(record)
  File "/home/jaansi/miniconda3/lib/python3.12/site-packages/wandb/sdk/lib/sock_client.py", line 174, in send_record_publish
    self.send_server_request(server_req)
  File "/home/jaansi/miniconda3/lib/python3.12/site-packages/wandb/sdk/lib/sock_client.py", line 154, in send_server_request
    self._send_message(msg)
  File "/home/jaansi/miniconda3/lib/python3.12/site-packages/wandb/sdk/lib/sock_client.py", line 151, in _send_message
    self._sendall_with_error_handle(header + data)
  File "/home/jaansi/miniconda3/lib/python3.12/site-packages/wandb/sdk/lib/sock_client.py", line 130, in _sendall_with_error_handle
    sent = self._sock.send(data)
           ^^^^^^^^^^^^^^^^^^^^^
BrokenPipeError: [Errno 32] Broken pipe
2025-03-18 01:24:09,503 ERROR   Thread-18 (_pin_memory_loop):1694815 [redirect.py:_on_write():661] error in stderr callback
Traceback (most recent call last):
  File "/home/jaansi/miniconda3/lib/python3.12/threading.py", line 1075, in _bootstrap_inner
    self.run()
  File "/home/jaansi/miniconda3/lib/python3.12/threading.py", line 1012, in run
    self._target(*self._args, **self._kwargs)
  File "/home/jaansi/miniconda3/lib/python3.12/site-packages/torch/utils/data/_utils/pin_memory.py", line 59, in _pin_memory_loop
    do_one_step()
  File "/home/jaansi/miniconda3/lib/python3.12/site-packages/torch/utils/data/_utils/pin_memory.py", line 35, in do_one_step
    r = in_queue.get(timeout=MP_STATUS_CHECK_INTERVAL)
        ^^^^^^^^^^^^^^^^^^^^^^^^^^^^^^^^^^^^^^^^^^^^^^
  File "/home/jaansi/miniconda3/lib/python3.12/multiprocessing/queues.py", line 122, in get
    return _ForkingPickler.loads(res)
           ^^^^^^^^^^^^^^^^^^^^^^^^^^
  File "/home/jaansi/miniconda3/lib/python3.12/site-packages/torch/multiprocessing/reductions.py", line 541, in rebuild_storage_fd
    fd = df.detach()
         ^^^^^^^^^^^
  File "/home/jaansi/miniconda3/lib/python3.12/multiprocessing/resource_sharer.py", line 57, in detach
    with _resource_sharer.get_connection(self._id) as conn:
         ^^^^^^^^^^^^^^^^^^^^^^^^^^^^^^^^^^^^^^^^^
  File "/home/jaansi/miniconda3/lib/python3.12/multiprocessing/resource_sharer.py", line 86, in get_connection
    c = Client(address, authkey=process.current_process().authkey)
        ^^^^^^^^^^^^^^^^^^^^^^^^^^^^^^^^^^^^^^^^^^^^^^^^^^^^^^^^^^
  File "/home/jaansi/miniconda3/lib/python3.12/multiprocessing/connection.py", line 525, in Client
    answer_challenge(c, authkey)
  File "/home/jaansi/miniconda3/lib/python3.12/multiprocessing/connection.py", line 953, in answer_challenge
    message = connection.recv_bytes(256)         # reject large message
              ^^^^^^^^^^^^^^^^^^^^^^^^^^
  File "/home/jaansi/miniconda3/lib/python3.12/multiprocessing/connection.py", line 216, in recv_bytes
    buf = self._recv_bytes(maxlength)
          ^^^^^^^^^^^^^^^^^^^^^^^^^^^
  File "/home/jaansi/miniconda3/lib/python3.12/multiprocessing/connection.py", line 430, in _recv_bytes
    buf = self._recv(4)
          ^^^^^^^^^^^^^
  File "/home/jaansi/miniconda3/lib/python3.12/multiprocessing/connection.py", line 395, in _recv
    chunk = read(handle, remaining)
            ^^^^^^^^^^^^^^^^^^^^^^^
ConnectionResetError: [Errno 104] Connection reset by peer

During handling of the above exception, another exception occurred:

Traceback (most recent call last):
  File "/home/jaansi/miniconda3/lib/python3.12/site-packages/wandb/sdk/lib/redirect.py", line 659, in _on_write
    cb(written_data)
  File "/home/jaansi/miniconda3/lib/python3.12/site-packages/wandb/sdk/wandb_run.py", line 2302, in <lambda>
    lambda data: self._console_raw_callback("stderr", data),
                 ^^^^^^^^^^^^^^^^^^^^^^^^^^^^^^^^^^^^^^^^^^
  File "/home/jaansi/miniconda3/lib/python3.12/site-packages/wandb/sdk/wandb_run.py", line 401, in wrapper_fn
    return func(self, *args, **kwargs)
           ^^^^^^^^^^^^^^^^^^^^^^^^^^^
  File "/home/jaansi/miniconda3/lib/python3.12/site-packages/wandb/sdk/wandb_run.py", line 1444, in _console_raw_callback
    self._backend.interface.publish_output_raw(name, data)
  File "/home/jaansi/miniconda3/lib/python3.12/site-packages/wandb/sdk/interface/interface.py", line 761, in publish_output_raw
    self._publish_output_raw(o)
  File "/home/jaansi/miniconda3/lib/python3.12/site-packages/wandb/sdk/interface/interface_shared.py", line 38, in _publish_output_raw
    self._publish(rec)
  File "/home/jaansi/miniconda3/lib/python3.12/site-packages/wandb/sdk/interface/interface_sock.py", line 39, in _publish
    self._sock_client.send_record_publish(record)
  File "/home/jaansi/miniconda3/lib/python3.12/site-packages/wandb/sdk/lib/sock_client.py", line 174, in send_record_publish
    self.send_server_request(server_req)
  File "/home/jaansi/miniconda3/lib/python3.12/site-packages/wandb/sdk/lib/sock_client.py", line 154, in send_server_request
    self._send_message(msg)
  File "/home/jaansi/miniconda3/lib/python3.12/site-packages/wandb/sdk/lib/sock_client.py", line 151, in _send_message
    self._sendall_with_error_handle(header + data)
  File "/home/jaansi/miniconda3/lib/python3.12/site-packages/wandb/sdk/lib/sock_client.py", line 130, in _sendall_with_error_handle
    sent = self._sock.send(data)
           ^^^^^^^^^^^^^^^^^^^^^
BrokenPipeError: [Errno 32] Broken pipe
2025-03-18 01:24:09,504 ERROR   Thread-18 (_pin_memory_loop):1694815 [redirect.py:_on_write():661] error in stderr callback
Traceback (most recent call last):
  File "/home/jaansi/miniconda3/lib/python3.12/threading.py", line 1075, in _bootstrap_inner
    self.run()
  File "/home/jaansi/miniconda3/lib/python3.12/threading.py", line 1012, in run
    self._target(*self._args, **self._kwargs)
  File "/home/jaansi/miniconda3/lib/python3.12/site-packages/torch/utils/data/_utils/pin_memory.py", line 59, in _pin_memory_loop
    do_one_step()
  File "/home/jaansi/miniconda3/lib/python3.12/site-packages/torch/utils/data/_utils/pin_memory.py", line 35, in do_one_step
    r = in_queue.get(timeout=MP_STATUS_CHECK_INTERVAL)
        ^^^^^^^^^^^^^^^^^^^^^^^^^^^^^^^^^^^^^^^^^^^^^^
  File "/home/jaansi/miniconda3/lib/python3.12/multiprocessing/queues.py", line 122, in get
    return _ForkingPickler.loads(res)
           ^^^^^^^^^^^^^^^^^^^^^^^^^^
  File "/home/jaansi/miniconda3/lib/python3.12/site-packages/torch/multiprocessing/reductions.py", line 541, in rebuild_storage_fd
    fd = df.detach()
         ^^^^^^^^^^^
  File "/home/jaansi/miniconda3/lib/python3.12/multiprocessing/resource_sharer.py", line 57, in detach
    with _resource_sharer.get_connection(self._id) as conn:
         ^^^^^^^^^^^^^^^^^^^^^^^^^^^^^^^^^^^^^^^^^
  File "/home/jaansi/miniconda3/lib/python3.12/multiprocessing/resource_sharer.py", line 86, in get_connection
    c = Client(address, authkey=process.current_process().authkey)
        ^^^^^^^^^^^^^^^^^^^^^^^^^^^^^^^^^^^^^^^^^^^^^^^^^^^^^^^^^^
  File "/home/jaansi/miniconda3/lib/python3.12/multiprocessing/connection.py", line 525, in Client
    answer_challenge(c, authkey)
  File "/home/jaansi/miniconda3/lib/python3.12/multiprocessing/connection.py", line 953, in answer_challenge
    message = connection.recv_bytes(256)         # reject large message
              ^^^^^^^^^^^^^^^^^^^^^^^^^^
  File "/home/jaansi/miniconda3/lib/python3.12/multiprocessing/connection.py", line 216, in recv_bytes
    buf = self._recv_bytes(maxlength)
          ^^^^^^^^^^^^^^^^^^^^^^^^^^^
  File "/home/jaansi/miniconda3/lib/python3.12/multiprocessing/connection.py", line 430, in _recv_bytes
    buf = self._recv(4)
          ^^^^^^^^^^^^^
  File "/home/jaansi/miniconda3/lib/python3.12/multiprocessing/connection.py", line 395, in _recv
    chunk = read(handle, remaining)
            ^^^^^^^^^^^^^^^^^^^^^^^
ConnectionResetError: [Errno 104] Connection reset by peer

During handling of the above exception, another exception occurred:

Traceback (most recent call last):
  File "/home/jaansi/miniconda3/lib/python3.12/site-packages/wandb/sdk/lib/redirect.py", line 659, in _on_write
    cb(written_data)
  File "/home/jaansi/miniconda3/lib/python3.12/site-packages/wandb/sdk/wandb_run.py", line 2302, in <lambda>
    lambda data: self._console_raw_callback("stderr", data),
                 ^^^^^^^^^^^^^^^^^^^^^^^^^^^^^^^^^^^^^^^^^^
  File "/home/jaansi/miniconda3/lib/python3.12/site-packages/wandb/sdk/wandb_run.py", line 401, in wrapper_fn
    return func(self, *args, **kwargs)
           ^^^^^^^^^^^^^^^^^^^^^^^^^^^
  File "/home/jaansi/miniconda3/lib/python3.12/site-packages/wandb/sdk/wandb_run.py", line 1444, in _console_raw_callback
    self._backend.interface.publish_output_raw(name, data)
  File "/home/jaansi/miniconda3/lib/python3.12/site-packages/wandb/sdk/interface/interface.py", line 761, in publish_output_raw
    self._publish_output_raw(o)
  File "/home/jaansi/miniconda3/lib/python3.12/site-packages/wandb/sdk/interface/interface_shared.py", line 38, in _publish_output_raw
    self._publish(rec)
  File "/home/jaansi/miniconda3/lib/python3.12/site-packages/wandb/sdk/interface/interface_sock.py", line 39, in _publish
    self._sock_client.send_record_publish(record)
  File "/home/jaansi/miniconda3/lib/python3.12/site-packages/wandb/sdk/lib/sock_client.py", line 174, in send_record_publish
    self.send_server_request(server_req)
  File "/home/jaansi/miniconda3/lib/python3.12/site-packages/wandb/sdk/lib/sock_client.py", line 154, in send_server_request
    self._send_message(msg)
  File "/home/jaansi/miniconda3/lib/python3.12/site-packages/wandb/sdk/lib/sock_client.py", line 151, in _send_message
    self._sendall_with_error_handle(header + data)
  File "/home/jaansi/miniconda3/lib/python3.12/site-packages/wandb/sdk/lib/sock_client.py", line 130, in _sendall_with_error_handle
    sent = self._sock.send(data)
           ^^^^^^^^^^^^^^^^^^^^^
BrokenPipeError: [Errno 32] Broken pipe
2025-03-18 01:24:09,505 ERROR   Thread-18 (_pin_memory_loop):1694815 [redirect.py:_on_write():661] error in stderr callback
Traceback (most recent call last):
  File "/home/jaansi/miniconda3/lib/python3.12/threading.py", line 1075, in _bootstrap_inner
    self.run()
  File "/home/jaansi/miniconda3/lib/python3.12/threading.py", line 1012, in run
    self._target(*self._args, **self._kwargs)
  File "/home/jaansi/miniconda3/lib/python3.12/site-packages/torch/utils/data/_utils/pin_memory.py", line 59, in _pin_memory_loop
    do_one_step()
  File "/home/jaansi/miniconda3/lib/python3.12/site-packages/torch/utils/data/_utils/pin_memory.py", line 35, in do_one_step
    r = in_queue.get(timeout=MP_STATUS_CHECK_INTERVAL)
        ^^^^^^^^^^^^^^^^^^^^^^^^^^^^^^^^^^^^^^^^^^^^^^
  File "/home/jaansi/miniconda3/lib/python3.12/multiprocessing/queues.py", line 122, in get
    return _ForkingPickler.loads(res)
           ^^^^^^^^^^^^^^^^^^^^^^^^^^
  File "/home/jaansi/miniconda3/lib/python3.12/site-packages/torch/multiprocessing/reductions.py", line 541, in rebuild_storage_fd
    fd = df.detach()
         ^^^^^^^^^^^
  File "/home/jaansi/miniconda3/lib/python3.12/multiprocessing/resource_sharer.py", line 57, in detach
    with _resource_sharer.get_connection(self._id) as conn:
         ^^^^^^^^^^^^^^^^^^^^^^^^^^^^^^^^^^^^^^^^^
  File "/home/jaansi/miniconda3/lib/python3.12/multiprocessing/resource_sharer.py", line 86, in get_connection
    c = Client(address, authkey=process.current_process().authkey)
        ^^^^^^^^^^^^^^^^^^^^^^^^^^^^^^^^^^^^^^^^^^^^^^^^^^^^^^^^^^
  File "/home/jaansi/miniconda3/lib/python3.12/multiprocessing/connection.py", line 525, in Client
    answer_challenge(c, authkey)
  File "/home/jaansi/miniconda3/lib/python3.12/multiprocessing/connection.py", line 953, in answer_challenge
    message = connection.recv_bytes(256)         # reject large message
              ^^^^^^^^^^^^^^^^^^^^^^^^^^
  File "/home/jaansi/miniconda3/lib/python3.12/multiprocessing/connection.py", line 216, in recv_bytes
    buf = self._recv_bytes(maxlength)
          ^^^^^^^^^^^^^^^^^^^^^^^^^^^
  File "/home/jaansi/miniconda3/lib/python3.12/multiprocessing/connection.py", line 430, in _recv_bytes
    buf = self._recv(4)
          ^^^^^^^^^^^^^
  File "/home/jaansi/miniconda3/lib/python3.12/multiprocessing/connection.py", line 395, in _recv
    chunk = read(handle, remaining)
            ^^^^^^^^^^^^^^^^^^^^^^^
ConnectionResetError: [Errno 104] Connection reset by peer

During handling of the above exception, another exception occurred:

Traceback (most recent call last):
  File "/home/jaansi/miniconda3/lib/python3.12/site-packages/wandb/sdk/lib/redirect.py", line 659, in _on_write
    cb(written_data)
  File "/home/jaansi/miniconda3/lib/python3.12/site-packages/wandb/sdk/wandb_run.py", line 2302, in <lambda>
    lambda data: self._console_raw_callback("stderr", data),
                 ^^^^^^^^^^^^^^^^^^^^^^^^^^^^^^^^^^^^^^^^^^
  File "/home/jaansi/miniconda3/lib/python3.12/site-packages/wandb/sdk/wandb_run.py", line 401, in wrapper_fn
    return func(self, *args, **kwargs)
           ^^^^^^^^^^^^^^^^^^^^^^^^^^^
  File "/home/jaansi/miniconda3/lib/python3.12/site-packages/wandb/sdk/wandb_run.py", line 1444, in _console_raw_callback
    self._backend.interface.publish_output_raw(name, data)
  File "/home/jaansi/miniconda3/lib/python3.12/site-packages/wandb/sdk/interface/interface.py", line 761, in publish_output_raw
    self._publish_output_raw(o)
  File "/home/jaansi/miniconda3/lib/python3.12/site-packages/wandb/sdk/interface/interface_shared.py", line 38, in _publish_output_raw
    self._publish(rec)
  File "/home/jaansi/miniconda3/lib/python3.12/site-packages/wandb/sdk/interface/interface_sock.py", line 39, in _publish
    self._sock_client.send_record_publish(record)
  File "/home/jaansi/miniconda3/lib/python3.12/site-packages/wandb/sdk/lib/sock_client.py", line 174, in send_record_publish
    self.send_server_request(server_req)
  File "/home/jaansi/miniconda3/lib/python3.12/site-packages/wandb/sdk/lib/sock_client.py", line 154, in send_server_request
    self._send_message(msg)
  File "/home/jaansi/miniconda3/lib/python3.12/site-packages/wandb/sdk/lib/sock_client.py", line 151, in _send_message
    self._sendall_with_error_handle(header + data)
  File "/home/jaansi/miniconda3/lib/python3.12/site-packages/wandb/sdk/lib/sock_client.py", line 130, in _sendall_with_error_handle
    sent = self._sock.send(data)
           ^^^^^^^^^^^^^^^^^^^^^
BrokenPipeError: [Errno 32] Broken pipe
2025-03-18 01:24:09,506 ERROR   Thread-18 (_pin_memory_loop):1694815 [redirect.py:_on_write():661] error in stderr callback
Traceback (most recent call last):
  File "/home/jaansi/miniconda3/lib/python3.12/threading.py", line 1075, in _bootstrap_inner
    self.run()
  File "/home/jaansi/miniconda3/lib/python3.12/threading.py", line 1012, in run
    self._target(*self._args, **self._kwargs)
  File "/home/jaansi/miniconda3/lib/python3.12/site-packages/torch/utils/data/_utils/pin_memory.py", line 59, in _pin_memory_loop
    do_one_step()
  File "/home/jaansi/miniconda3/lib/python3.12/site-packages/torch/utils/data/_utils/pin_memory.py", line 35, in do_one_step
    r = in_queue.get(timeout=MP_STATUS_CHECK_INTERVAL)
        ^^^^^^^^^^^^^^^^^^^^^^^^^^^^^^^^^^^^^^^^^^^^^^
  File "/home/jaansi/miniconda3/lib/python3.12/multiprocessing/queues.py", line 122, in get
    return _ForkingPickler.loads(res)
           ^^^^^^^^^^^^^^^^^^^^^^^^^^
  File "/home/jaansi/miniconda3/lib/python3.12/site-packages/torch/multiprocessing/reductions.py", line 541, in rebuild_storage_fd
    fd = df.detach()
         ^^^^^^^^^^^
  File "/home/jaansi/miniconda3/lib/python3.12/multiprocessing/resource_sharer.py", line 57, in detach
    with _resource_sharer.get_connection(self._id) as conn:
         ^^^^^^^^^^^^^^^^^^^^^^^^^^^^^^^^^^^^^^^^^
  File "/home/jaansi/miniconda3/lib/python3.12/multiprocessing/resource_sharer.py", line 86, in get_connection
    c = Client(address, authkey=process.current_process().authkey)
        ^^^^^^^^^^^^^^^^^^^^^^^^^^^^^^^^^^^^^^^^^^^^^^^^^^^^^^^^^^
  File "/home/jaansi/miniconda3/lib/python3.12/multiprocessing/connection.py", line 525, in Client
    answer_challenge(c, authkey)
  File "/home/jaansi/miniconda3/lib/python3.12/multiprocessing/connection.py", line 953, in answer_challenge
    message = connection.recv_bytes(256)         # reject large message
              ^^^^^^^^^^^^^^^^^^^^^^^^^^
  File "/home/jaansi/miniconda3/lib/python3.12/multiprocessing/connection.py", line 216, in recv_bytes
    buf = self._recv_bytes(maxlength)
          ^^^^^^^^^^^^^^^^^^^^^^^^^^^
  File "/home/jaansi/miniconda3/lib/python3.12/multiprocessing/connection.py", line 430, in _recv_bytes
    buf = self._recv(4)
          ^^^^^^^^^^^^^
  File "/home/jaansi/miniconda3/lib/python3.12/multiprocessing/connection.py", line 395, in _recv
    chunk = read(handle, remaining)
            ^^^^^^^^^^^^^^^^^^^^^^^
ConnectionResetError: [Errno 104] Connection reset by peer

During handling of the above exception, another exception occurred:

Traceback (most recent call last):
  File "/home/jaansi/miniconda3/lib/python3.12/site-packages/wandb/sdk/lib/redirect.py", line 659, in _on_write
    cb(written_data)
  File "/home/jaansi/miniconda3/lib/python3.12/site-packages/wandb/sdk/wandb_run.py", line 2302, in <lambda>
    lambda data: self._console_raw_callback("stderr", data),
                 ^^^^^^^^^^^^^^^^^^^^^^^^^^^^^^^^^^^^^^^^^^
  File "/home/jaansi/miniconda3/lib/python3.12/site-packages/wandb/sdk/wandb_run.py", line 401, in wrapper_fn
    return func(self, *args, **kwargs)
           ^^^^^^^^^^^^^^^^^^^^^^^^^^^
  File "/home/jaansi/miniconda3/lib/python3.12/site-packages/wandb/sdk/wandb_run.py", line 1444, in _console_raw_callback
    self._backend.interface.publish_output_raw(name, data)
  File "/home/jaansi/miniconda3/lib/python3.12/site-packages/wandb/sdk/interface/interface.py", line 761, in publish_output_raw
    self._publish_output_raw(o)
  File "/home/jaansi/miniconda3/lib/python3.12/site-packages/wandb/sdk/interface/interface_shared.py", line 38, in _publish_output_raw
    self._publish(rec)
  File "/home/jaansi/miniconda3/lib/python3.12/site-packages/wandb/sdk/interface/interface_sock.py", line 39, in _publish
    self._sock_client.send_record_publish(record)
  File "/home/jaansi/miniconda3/lib/python3.12/site-packages/wandb/sdk/lib/sock_client.py", line 174, in send_record_publish
    self.send_server_request(server_req)
  File "/home/jaansi/miniconda3/lib/python3.12/site-packages/wandb/sdk/lib/sock_client.py", line 154, in send_server_request
    self._send_message(msg)
  File "/home/jaansi/miniconda3/lib/python3.12/site-packages/wandb/sdk/lib/sock_client.py", line 151, in _send_message
    self._sendall_with_error_handle(header + data)
  File "/home/jaansi/miniconda3/lib/python3.12/site-packages/wandb/sdk/lib/sock_client.py", line 130, in _sendall_with_error_handle
    sent = self._sock.send(data)
           ^^^^^^^^^^^^^^^^^^^^^
BrokenPipeError: [Errno 32] Broken pipe
2025-03-18 01:24:09,508 ERROR   Thread-18 (_pin_memory_loop):1694815 [redirect.py:_on_write():661] error in stderr callback
Traceback (most recent call last):
  File "/home/jaansi/miniconda3/lib/python3.12/threading.py", line 1075, in _bootstrap_inner
    self.run()
  File "/home/jaansi/miniconda3/lib/python3.12/threading.py", line 1012, in run
    self._target(*self._args, **self._kwargs)
  File "/home/jaansi/miniconda3/lib/python3.12/site-packages/torch/utils/data/_utils/pin_memory.py", line 59, in _pin_memory_loop
    do_one_step()
  File "/home/jaansi/miniconda3/lib/python3.12/site-packages/torch/utils/data/_utils/pin_memory.py", line 35, in do_one_step
    r = in_queue.get(timeout=MP_STATUS_CHECK_INTERVAL)
        ^^^^^^^^^^^^^^^^^^^^^^^^^^^^^^^^^^^^^^^^^^^^^^
  File "/home/jaansi/miniconda3/lib/python3.12/multiprocessing/queues.py", line 122, in get
    return _ForkingPickler.loads(res)
           ^^^^^^^^^^^^^^^^^^^^^^^^^^
  File "/home/jaansi/miniconda3/lib/python3.12/site-packages/torch/multiprocessing/reductions.py", line 541, in rebuild_storage_fd
    fd = df.detach()
         ^^^^^^^^^^^
  File "/home/jaansi/miniconda3/lib/python3.12/multiprocessing/resource_sharer.py", line 57, in detach
    with _resource_sharer.get_connection(self._id) as conn:
         ^^^^^^^^^^^^^^^^^^^^^^^^^^^^^^^^^^^^^^^^^
  File "/home/jaansi/miniconda3/lib/python3.12/multiprocessing/resource_sharer.py", line 86, in get_connection
    c = Client(address, authkey=process.current_process().authkey)
        ^^^^^^^^^^^^^^^^^^^^^^^^^^^^^^^^^^^^^^^^^^^^^^^^^^^^^^^^^^
  File "/home/jaansi/miniconda3/lib/python3.12/multiprocessing/connection.py", line 525, in Client
    answer_challenge(c, authkey)
  File "/home/jaansi/miniconda3/lib/python3.12/multiprocessing/connection.py", line 953, in answer_challenge
    message = connection.recv_bytes(256)         # reject large message
              ^^^^^^^^^^^^^^^^^^^^^^^^^^
  File "/home/jaansi/miniconda3/lib/python3.12/multiprocessing/connection.py", line 216, in recv_bytes
    buf = self._recv_bytes(maxlength)
          ^^^^^^^^^^^^^^^^^^^^^^^^^^^
  File "/home/jaansi/miniconda3/lib/python3.12/multiprocessing/connection.py", line 430, in _recv_bytes
    buf = self._recv(4)
          ^^^^^^^^^^^^^
  File "/home/jaansi/miniconda3/lib/python3.12/multiprocessing/connection.py", line 395, in _recv
    chunk = read(handle, remaining)
            ^^^^^^^^^^^^^^^^^^^^^^^
ConnectionResetError: [Errno 104] Connection reset by peer

During handling of the above exception, another exception occurred:

Traceback (most recent call last):
  File "/home/jaansi/miniconda3/lib/python3.12/site-packages/wandb/sdk/lib/redirect.py", line 659, in _on_write
    cb(written_data)
  File "/home/jaansi/miniconda3/lib/python3.12/site-packages/wandb/sdk/wandb_run.py", line 2302, in <lambda>
    lambda data: self._console_raw_callback("stderr", data),
                 ^^^^^^^^^^^^^^^^^^^^^^^^^^^^^^^^^^^^^^^^^^
  File "/home/jaansi/miniconda3/lib/python3.12/site-packages/wandb/sdk/wandb_run.py", line 401, in wrapper_fn
    return func(self, *args, **kwargs)
           ^^^^^^^^^^^^^^^^^^^^^^^^^^^
  File "/home/jaansi/miniconda3/lib/python3.12/site-packages/wandb/sdk/wandb_run.py", line 1444, in _console_raw_callback
    self._backend.interface.publish_output_raw(name, data)
  File "/home/jaansi/miniconda3/lib/python3.12/site-packages/wandb/sdk/interface/interface.py", line 761, in publish_output_raw
    self._publish_output_raw(o)
  File "/home/jaansi/miniconda3/lib/python3.12/site-packages/wandb/sdk/interface/interface_shared.py", line 38, in _publish_output_raw
    self._publish(rec)
  File "/home/jaansi/miniconda3/lib/python3.12/site-packages/wandb/sdk/interface/interface_sock.py", line 39, in _publish
    self._sock_client.send_record_publish(record)
  File "/home/jaansi/miniconda3/lib/python3.12/site-packages/wandb/sdk/lib/sock_client.py", line 174, in send_record_publish
    self.send_server_request(server_req)
  File "/home/jaansi/miniconda3/lib/python3.12/site-packages/wandb/sdk/lib/sock_client.py", line 154, in send_server_request
    self._send_message(msg)
  File "/home/jaansi/miniconda3/lib/python3.12/site-packages/wandb/sdk/lib/sock_client.py", line 151, in _send_message
    self._sendall_with_error_handle(header + data)
  File "/home/jaansi/miniconda3/lib/python3.12/site-packages/wandb/sdk/lib/sock_client.py", line 130, in _sendall_with_error_handle
    sent = self._sock.send(data)
           ^^^^^^^^^^^^^^^^^^^^^
BrokenPipeError: [Errno 32] Broken pipe
2025-03-18 01:24:09,508 ERROR   Thread-18 (_pin_memory_loop):1694815 [redirect.py:_on_write():661] error in stderr callback
Traceback (most recent call last):
  File "/home/jaansi/miniconda3/lib/python3.12/threading.py", line 1075, in _bootstrap_inner
    self.run()
  File "/home/jaansi/miniconda3/lib/python3.12/threading.py", line 1012, in run
    self._target(*self._args, **self._kwargs)
  File "/home/jaansi/miniconda3/lib/python3.12/site-packages/torch/utils/data/_utils/pin_memory.py", line 59, in _pin_memory_loop
    do_one_step()
  File "/home/jaansi/miniconda3/lib/python3.12/site-packages/torch/utils/data/_utils/pin_memory.py", line 35, in do_one_step
    r = in_queue.get(timeout=MP_STATUS_CHECK_INTERVAL)
        ^^^^^^^^^^^^^^^^^^^^^^^^^^^^^^^^^^^^^^^^^^^^^^
  File "/home/jaansi/miniconda3/lib/python3.12/multiprocessing/queues.py", line 122, in get
    return _ForkingPickler.loads(res)
           ^^^^^^^^^^^^^^^^^^^^^^^^^^
  File "/home/jaansi/miniconda3/lib/python3.12/site-packages/torch/multiprocessing/reductions.py", line 541, in rebuild_storage_fd
    fd = df.detach()
         ^^^^^^^^^^^
  File "/home/jaansi/miniconda3/lib/python3.12/multiprocessing/resource_sharer.py", line 57, in detach
    with _resource_sharer.get_connection(self._id) as conn:
         ^^^^^^^^^^^^^^^^^^^^^^^^^^^^^^^^^^^^^^^^^
  File "/home/jaansi/miniconda3/lib/python3.12/multiprocessing/resource_sharer.py", line 86, in get_connection
    c = Client(address, authkey=process.current_process().authkey)
        ^^^^^^^^^^^^^^^^^^^^^^^^^^^^^^^^^^^^^^^^^^^^^^^^^^^^^^^^^^
  File "/home/jaansi/miniconda3/lib/python3.12/multiprocessing/connection.py", line 525, in Client
    answer_challenge(c, authkey)
  File "/home/jaansi/miniconda3/lib/python3.12/multiprocessing/connection.py", line 953, in answer_challenge
    message = connection.recv_bytes(256)         # reject large message
              ^^^^^^^^^^^^^^^^^^^^^^^^^^
  File "/home/jaansi/miniconda3/lib/python3.12/multiprocessing/connection.py", line 216, in recv_bytes
    buf = self._recv_bytes(maxlength)
          ^^^^^^^^^^^^^^^^^^^^^^^^^^^
  File "/home/jaansi/miniconda3/lib/python3.12/multiprocessing/connection.py", line 430, in _recv_bytes
    buf = self._recv(4)
          ^^^^^^^^^^^^^
  File "/home/jaansi/miniconda3/lib/python3.12/multiprocessing/connection.py", line 395, in _recv
    chunk = read(handle, remaining)
            ^^^^^^^^^^^^^^^^^^^^^^^
ConnectionResetError: [Errno 104] Connection reset by peer

During handling of the above exception, another exception occurred:

Traceback (most recent call last):
  File "/home/jaansi/miniconda3/lib/python3.12/site-packages/wandb/sdk/lib/redirect.py", line 659, in _on_write
    cb(written_data)
  File "/home/jaansi/miniconda3/lib/python3.12/site-packages/wandb/sdk/wandb_run.py", line 2302, in <lambda>
    lambda data: self._console_raw_callback("stderr", data),
                 ^^^^^^^^^^^^^^^^^^^^^^^^^^^^^^^^^^^^^^^^^^
  File "/home/jaansi/miniconda3/lib/python3.12/site-packages/wandb/sdk/wandb_run.py", line 401, in wrapper_fn
    return func(self, *args, **kwargs)
           ^^^^^^^^^^^^^^^^^^^^^^^^^^^
  File "/home/jaansi/miniconda3/lib/python3.12/site-packages/wandb/sdk/wandb_run.py", line 1444, in _console_raw_callback
    self._backend.interface.publish_output_raw(name, data)
  File "/home/jaansi/miniconda3/lib/python3.12/site-packages/wandb/sdk/interface/interface.py", line 761, in publish_output_raw
    self._publish_output_raw(o)
  File "/home/jaansi/miniconda3/lib/python3.12/site-packages/wandb/sdk/interface/interface_shared.py", line 38, in _publish_output_raw
    self._publish(rec)
  File "/home/jaansi/miniconda3/lib/python3.12/site-packages/wandb/sdk/interface/interface_sock.py", line 39, in _publish
    self._sock_client.send_record_publish(record)
  File "/home/jaansi/miniconda3/lib/python3.12/site-packages/wandb/sdk/lib/sock_client.py", line 174, in send_record_publish
    self.send_server_request(server_req)
  File "/home/jaansi/miniconda3/lib/python3.12/site-packages/wandb/sdk/lib/sock_client.py", line 154, in send_server_request
    self._send_message(msg)
  File "/home/jaansi/miniconda3/lib/python3.12/site-packages/wandb/sdk/lib/sock_client.py", line 151, in _send_message
    self._sendall_with_error_handle(header + data)
  File "/home/jaansi/miniconda3/lib/python3.12/site-packages/wandb/sdk/lib/sock_client.py", line 130, in _sendall_with_error_handle
    sent = self._sock.send(data)
           ^^^^^^^^^^^^^^^^^^^^^
BrokenPipeError: [Errno 32] Broken pipe
2025-03-18 01:24:09,509 ERROR   Thread-18 (_pin_memory_loop):1694815 [redirect.py:_on_write():661] error in stderr callback
Traceback (most recent call last):
  File "/home/jaansi/miniconda3/lib/python3.12/threading.py", line 1075, in _bootstrap_inner
    self.run()
  File "/home/jaansi/miniconda3/lib/python3.12/threading.py", line 1012, in run
    self._target(*self._args, **self._kwargs)
  File "/home/jaansi/miniconda3/lib/python3.12/site-packages/torch/utils/data/_utils/pin_memory.py", line 59, in _pin_memory_loop
    do_one_step()
  File "/home/jaansi/miniconda3/lib/python3.12/site-packages/torch/utils/data/_utils/pin_memory.py", line 35, in do_one_step
    r = in_queue.get(timeout=MP_STATUS_CHECK_INTERVAL)
        ^^^^^^^^^^^^^^^^^^^^^^^^^^^^^^^^^^^^^^^^^^^^^^
  File "/home/jaansi/miniconda3/lib/python3.12/multiprocessing/queues.py", line 122, in get
    return _ForkingPickler.loads(res)
           ^^^^^^^^^^^^^^^^^^^^^^^^^^
  File "/home/jaansi/miniconda3/lib/python3.12/site-packages/torch/multiprocessing/reductions.py", line 541, in rebuild_storage_fd
    fd = df.detach()
         ^^^^^^^^^^^
  File "/home/jaansi/miniconda3/lib/python3.12/multiprocessing/resource_sharer.py", line 57, in detach
    with _resource_sharer.get_connection(self._id) as conn:
         ^^^^^^^^^^^^^^^^^^^^^^^^^^^^^^^^^^^^^^^^^
  File "/home/jaansi/miniconda3/lib/python3.12/multiprocessing/resource_sharer.py", line 86, in get_connection
    c = Client(address, authkey=process.current_process().authkey)
        ^^^^^^^^^^^^^^^^^^^^^^^^^^^^^^^^^^^^^^^^^^^^^^^^^^^^^^^^^^
  File "/home/jaansi/miniconda3/lib/python3.12/multiprocessing/connection.py", line 525, in Client
    answer_challenge(c, authkey)
  File "/home/jaansi/miniconda3/lib/python3.12/multiprocessing/connection.py", line 953, in answer_challenge
    message = connection.recv_bytes(256)         # reject large message
              ^^^^^^^^^^^^^^^^^^^^^^^^^^
  File "/home/jaansi/miniconda3/lib/python3.12/multiprocessing/connection.py", line 216, in recv_bytes
    buf = self._recv_bytes(maxlength)
          ^^^^^^^^^^^^^^^^^^^^^^^^^^^
  File "/home/jaansi/miniconda3/lib/python3.12/multiprocessing/connection.py", line 430, in _recv_bytes
    buf = self._recv(4)
          ^^^^^^^^^^^^^
  File "/home/jaansi/miniconda3/lib/python3.12/multiprocessing/connection.py", line 395, in _recv
    chunk = read(handle, remaining)
            ^^^^^^^^^^^^^^^^^^^^^^^
ConnectionResetError: [Errno 104] Connection reset by peer

During handling of the above exception, another exception occurred:

Traceback (most recent call last):
  File "/home/jaansi/miniconda3/lib/python3.12/site-packages/wandb/sdk/lib/redirect.py", line 659, in _on_write
    cb(written_data)
  File "/home/jaansi/miniconda3/lib/python3.12/site-packages/wandb/sdk/wandb_run.py", line 2302, in <lambda>
    lambda data: self._console_raw_callback("stderr", data),
                 ^^^^^^^^^^^^^^^^^^^^^^^^^^^^^^^^^^^^^^^^^^
  File "/home/jaansi/miniconda3/lib/python3.12/site-packages/wandb/sdk/wandb_run.py", line 401, in wrapper_fn
    return func(self, *args, **kwargs)
           ^^^^^^^^^^^^^^^^^^^^^^^^^^^
  File "/home/jaansi/miniconda3/lib/python3.12/site-packages/wandb/sdk/wandb_run.py", line 1444, in _console_raw_callback
    self._backend.interface.publish_output_raw(name, data)
  File "/home/jaansi/miniconda3/lib/python3.12/site-packages/wandb/sdk/interface/interface.py", line 761, in publish_output_raw
    self._publish_output_raw(o)
  File "/home/jaansi/miniconda3/lib/python3.12/site-packages/wandb/sdk/interface/interface_shared.py", line 38, in _publish_output_raw
    self._publish(rec)
  File "/home/jaansi/miniconda3/lib/python3.12/site-packages/wandb/sdk/interface/interface_sock.py", line 39, in _publish
    self._sock_client.send_record_publish(record)
  File "/home/jaansi/miniconda3/lib/python3.12/site-packages/wandb/sdk/lib/sock_client.py", line 174, in send_record_publish
    self.send_server_request(server_req)
  File "/home/jaansi/miniconda3/lib/python3.12/site-packages/wandb/sdk/lib/sock_client.py", line 154, in send_server_request
    self._send_message(msg)
  File "/home/jaansi/miniconda3/lib/python3.12/site-packages/wandb/sdk/lib/sock_client.py", line 151, in _send_message
    self._sendall_with_error_handle(header + data)
  File "/home/jaansi/miniconda3/lib/python3.12/site-packages/wandb/sdk/lib/sock_client.py", line 130, in _sendall_with_error_handle
    sent = self._sock.send(data)
           ^^^^^^^^^^^^^^^^^^^^^
BrokenPipeError: [Errno 32] Broken pipe
